Workbook

Sheet ปะหน้าAgingรายงานหนี้ค้าง บช.
A1: องค์การสะพานปลา
A2: รายงานหนี้ค้างชำระค่าเช่าและค่าธรรมเนียมต่าง ๆ
A3: ='agingปัจจุบันส่ง(ส่งบัญชี)'!A3 -> ณ วันที่ 31 กรกฎาคม 2569 | G3: เดือน พ.ค.69 | H3: G-E
A4: ลำดับ | C4: รายการ | E4: จำนวนเงิน
E5: (บาท)
A6: 1 | B6: สำนักงานสะพานปลากรุงเทพ
C7: รายได้ค้างรับประจำเดือนกรกฎาคม 2569
C8: ค่าเช่าอาคารและที่ดิน (4700400) | D8: =+'agingปัจจุบันส่ง(ส่งบัญชี)'!P96 -> 12610620 | G8: 11745695 | H8: =+D8-G8 -> 864924.75
C9: ค่าต่ออายุสัญญา/สิทธิการโอนฯ (4700900) | D9: =+'agingปัจจุบันส่ง(ส่งบัญชี)'!P106 -> 321983.48 | G9: 340943.63 | H9: =+D9-G9 -> -18960.15
C10: ค่าเช่าแฟลต (4600700) | D10: =+'agingปัจจุบันส่ง(ส่งบัญชี)'!P112 -> 6000 | G10: 11000 | H10: =+D10-G10 -> -5000
C11: บริการสัตว์น้ำ (4600100) | D11: =+'agingปัจจุบันส่ง(ส่งบัญชี)'!P239 -> 13673795 | G11: 13673795 | H11: =+D11-G11 -> 0
C12: ค่าธรรมเนียมใช้สถานที่ (4600700) | D12: =+'agingปัจจุบันส่ง(ส่งบัญชี)'!P213 -> 1602195.8 | G12: 1616422 | H12: =+D12-G12 -> -14226.24
C13: ค่าธรรมเนียมน้ำแข็งผ่านท่า 46000400 | D13: =+'agingปัจจุบันส่ง(ส่งบัญชี)'!P217 -> 0 | G13: 0 | H13: =+D13-G13 -> 0
C14: ค่าเช่าที่อื่นๆ 4700700 | D14: =+'agingปัจจุบันส่ง(ส่งบัญชี)'!P221 -> 0 | G14: 0 | H14: =+D14-G14 -> 0
C15: ค่าธรรมเนียมอื่นๆ 4600800 | D15: =+'agingปัจจุบันส่ง(ส่งบัญชี)'!P225 -> 0 | G15: 0 | H15: =+D15-G15 -> 0
C16: ค่าใช้สถานที่ทิ้งขยะ (4600700) | D16: =+'agingปัจจุบันส่ง(ส่งบัญชี)'!P228 -> 10272 | G16: 10272 | H16: =+D16-G16 -> 0
C17: ค่าจำหน่ายไฟฟ้า (4700300) | D17: =+'agingปัจจุบันส่ง(ส่งบัญชี)'!P159 -> 175936.85 | G17: 146254.77 | H17: =+D17-G17 -> 29682.08
C18: ค่าจำหน่ายน้ำประปา (4700200) | D18: =+'agingปัจจุบันส่ง(ส่งบัญชี)'!P194 -> 117232.23 | G18: 117729.51 | H18: =+D18-G18 -> -497.28
C19: ค่าเช่าที่จำหน่าย่น้ำแข็งและเครื่องโม่ (4601100) | D19: =+'agingปัจจุบันส่ง(ส่งบัญชี)'!P116 -> 63131.79 | G19: 63131.79 | H19: =+D19-G19 -> 0
C20: ค่าสุขาภิบาล (4701420) | D20: =+'agingปัจจุบันส่ง(ส่งบัญชี)'!P243 -> 0 | G20: 0 | H20: =+D20-G20 -> 0
C21: รายได้เบ็ดเตล็ด (ค่าภาษีโรงเรือน 4701600) | H21: =+D21-G21 -> 0
C22: - ภาษีโรงเรือน | D22: =+'agingปัจจุบันส่ง(ส่งบัญชี)'!P258 -> 415873.99 | G22: 419873.99 | H22: =+D22-G22 -> -4000
C23: - ประกันอัคคีภัย | E23: =SUM(D8:D22) -> 28997041 | I23: =+E23-G23 -> 28997041
A24: 2 | B24: สำนักงานสะพานปลาสมุทรปราการ | H24: =+D24-G24 -> 0
C25: =+C7 -> รายได้ค้างรับประจำเดือนกรกฎาคม 2569 | H25: =+D25-G25 -> 0
C26: ค่าเช่าอาคารและที่ดิน (4700400) | D26: =+'agingปัจจุบันส่ง(ส่งบัญชี)'!P279 -> 171035.24 | G26: 186155.24 | H26: =+D26-G26 -> -15120
C27: ค่าธรรมเนียมสัตว์น้ำผ่านท่า (4600200) | D27: =+'agingปัจจุบันส่ง(ส่งบัญชี)'!P283 -> 0 | G27: 0 | H27: =+D27-G27 -> 0
C28: ค่าธรรมเนียมรถผ่านท่า (4600300) | D28: =+'agingปัจจุบันส่ง(ส่งบัญชี)'!P287 -> 5350 | G28: 0 | H28: =+D28-G28 -> 5350
C29: ค่าธรรมเนียมน้ำแข็งผ่านท่า (4600400) | D29: =+'agingปัจจุบันส่ง(ส่งบัญชี)'!P295 -> 867369.35 | G29: 867369.35 | H29: =+D29-G29 -> 0
C30: ค่าธรรมเนียมใช้สถานที่ (4600700) | D30: =+'agingปัจจุบันส่ง(ส่งบัญชี)'!P312 -> 25145 | G30: 31000 | H30: =+D30-G30 -> -5855
C31: ค่าจำหน่ายน้ำประปา (4700200) | D31: =+'agingปัจจุบันส่ง(ส่งบัญชี)'!P316 -> 280.34 | G31: 0 | H31: =+D31-G31 -> 280.34
C32: ค่าจำหน่ายไฟฟ้า (4700300) | D32: =+'agingปัจจุบันส่ง(ส่งบัญชี)'!P320 -> 535 | G32: 5071.8024 | H32: =+D32-G32 -> -4536.8024
C33: ค่าสุขาภิบาล (4701420) | D33: =+'agingปัจจุบันส่ง(ส่งบัญชี)'!P336 -> 2354 | G33: 3424 | H33: =+D33-G33 -> -1070
C34: ค่าต่ออายุสัญญา/สิทธิการโอนฯ (4700900) | D34: =+'agingปัจจุบันส่ง(ส่งบัญชี)'!P340 -> 0 | G34: 11520 | H34: =+D34-G34 -> -11520
C35: รายได้เบ็ดเตล็ด (4701600) | H35: =+D35-G35 -> 0
C36: - ภาษีโรงเรือน | D36: =+'agingปัจจุบันส่ง(ส่งบัญชี)'!P347 -> 26201.52 | G36: 134215.43 | H36: =+D36-G36 -> -108013.91
C37: - ประกันอัคคีภัย | D37: =+'agingปัจจุบันส่ง(ส่งบัญชี)'!P352 -> 0 | E37: =SUM(D24:D37) -> 1098270.5 | G37: 0 | H37: =+D37-G37 -> 0
A38: =+A24+1 -> 3 | B38: สำนักงานสะพานปลาสมุทรสาคร | I38: =+E37-G38 -> 1098270.5
C39: =+C7 -> รายได้ค้างรับประจำเดือนกรกฎาคม 2569
C40: ค่าเช่าอาคารและที่ดิน (4700400) | D40: =+'agingปัจจุบันส่ง(ส่งบัญชี)'!P357 -> 0 | G40: 0
...

Sheet รับล่วงหน้า บช.
A1: องค์การสะพานปลา
A2: รายงานเงินรับล่วงหน้าค่าเช่าและค่าธรรมเนียมต่างๆ | M2: ปรับปรุง 29 กย.58
A3: =+'ปะหน้าAgingรายงานหนี้ค้าง บช.'!A3 -> ณ วันที่ 31 กรกฎาคม 2569
A4: ลำดับ | C4: รายการ | E4: จำนวนเงิน | I4: เดือนก่อน | J4: เพิ่ม/ลด
E5: (บาท)
A6: 1 | B6: สำนักงานสะพานปลากรุงเทพ
C7: เงินรับฝากประจำเดือนกรกฎาคม 2569
C8: ค่าเช่าอาคารและที่ดิน | D8: =+'agingปัจจุบันส่ง(ส่งบัญชี)'!Q96 -> 14253.86 | I8: 204995 | J8: =+D8-I8 -> -190741.14
C9: ค่าเช่าที่อื่นๆ | D9: =+'agingปัจจุบันส่ง(ส่งบัญชี)'!Q221 -> 0 | I9: 1400 | J9: =+D9-I9 -> -1400 | L9: ปริ้น 2 ใบ
C10: ค่าเช่าแฟลต | D10: ='agingปัจจุบันส่ง(ส่งบัญชี)'!Q112 -> 0 | I10: 0
C11: ค่าจำหน่ายไฟฟ้า | D11: =+'agingปัจจุบันส่ง(ส่งบัญชี)'!Q159 -> 0 | H11: =+E14-G14 -> 14253.86 | I11: 0 | J11: =+D11-I11 -> 0
C12: ค่าใช้สถานที่ | D12: =+'agingปัจจุบันส่ง(ส่งบัญชี)'!Q225 -> 0 | I12: 0 | J12: =+D12-I12 -> 0
C13: ค่าบริการสัตว์น้ำ | D13: =+'agingปัจจุบันส่ง(ส่งบัญชี)'!Q239 -> 0 | I13: 0
C14: ค่าจำหน่ายน้ำประปา | D14: =+'agingปัจจุบันส่ง(ส่งบัญชี)'!Q194 -> 0 | E14: =SUM(D8:D14) -> 14253.86 | G14: =+'agingปัจจุบันส่ง(ส่งบัญชี)'!D259 -> 0 | I14: 0 | J14: =+D14-I15 -> 0
A15: =+A6+1 -> 2 | B15: สำนักงานสะพานปลาสมุทรปราการ
C16: =+C7 -> เงินรับฝากประจำเดือนกรกฎาคม 2569
C17: ค่าเช่าอาคารและที่ดิน | D17: =+'agingปัจจุบันส่ง(ส่งบัญชี)'!Q279 -> 2184 | I17: 966028.5 | J17: =+D17-I17 -> -963844.5
C18: ค่าจำหน่ายน้ำประปา | D18: =+'agingปัจจุบันส่ง(ส่งบัญชี)'!Q316 -> 0 | I18: 0 | J18: =+D18-I18 -> 0
C19: ค่าจำหน่ายไฟฟ้า | D19: ='agingปัจจุบันส่ง(ส่งบัญชี)'!Q320 -> 0 | I19: 0 | J19: =+D19-I19 -> 0
C20: ค่าธรรมเนียมใช้สถานที่ | D20: =+'agingปัจจุบันส่ง(ส่งบัญชี)'!Q312 -> 18190 | I20: 12305 | J20: =+D20-I20 -> 5885
C21: ค่าธรรมเนียมรถผ่านท่า | D21: =+'agingปัจจุบันส่ง(ส่งบัญชี)'!Q287 -> 0 | I21: 0 | J21: =+D21-I21 -> 0
C22: ค่าธรรมเนียมสัตว์น้ำผ่านท่า | D22: =+'agingปัจจุบันส่ง(ส่งบัญชี)'!Q283 -> 0 | H22: =+E23-G23 -> 0 | I22: 0 | J22: =+D22-I22 -> 0
C23: ค่าภาษีโรงเรือน | D23: =+'agingปัจจุบันส่ง(ส่งบัญชี)'!Q347 -> 0 | G23: =+'agingปัจจุบันส่ง(ส่งบัญชี)'!D353 -> 0 | I23: 0 | J23: =+D23-I23 -> 0
C24: ค่าสุขาภิบาล | D24: =+'agingปัจจุบันส่ง(ส่งบัญชี)'!Q336 -> 428 | E24: =SUM(D17:D24) -> 20802
A25: =+A15+1 -> 3 | B25: สำนักงานท่าเทียบเรือประมงสมุทรสาคร
C26: =+C16 -> เงินรับฝากประจำเดือนกรกฎาคม 2569 | H26: =+E29-G29 -> 0
C27: ค่าเช่าอาคารและที่ดิน | D27: =+'agingปัจจุบันส่ง(ส่งบัญชี)'!Q373 -> 0 | I27: 0 | J27: =+D27-I27 -> 0
C28: ค่าเช่าที่อื่นๆ | D28: =+'agingปัจจุบันส่ง(ส่งบัญชี)'!Q361 -> 0 | I28: 0 | J28: =+D28-I28 -> 0
C29: ค่าธรรมเนียมใช้สถานที่ | D29: =+'agingปัจจุบันส่ง(ส่งบัญชี)'!Q364 -> 0 | E29: =SUM(D27:D29) -> 0 | G29: =+'agingปัจจุบันส่ง(ส่งบัญชี)'!D373 -> 0 | I29: 0 | J29: =+D29-I29 -> 0
A30: =+A25+1 -> 4 | B30: สำนักงานท่าเทียบเรือประมงตราด
C31: =+C16 -> เงินรับฝากประจำเดือนกรกฎาคม 2569
C32: ค่าเช่าอาคารและที่ดิน | D32: ='agingปัจจุบันส่ง(ส่งบัญชี)'!Q387 -> 36725.66 | H32: =+E35-G35 -> 38573.53 | I32: 15510.44 | J32: =+D32-I32 -> 21215.22
C33: ค่าเช่าที่อื่นๆ | D33: ='agingปัจจุบันส่ง(ส่งบัญชี)'!Q391 -> 0 | I33: 920
C34: ค่าใช้สถานที่ | D34: ='agingปัจจุบันส่ง(ส่งบัญชี)'!Q395 -> 0 | I34: 0 | J34: =+D34-I34 -> 0
C35: ค่าภาษีโรงเรือน | D35: =+'agingปัจจุบันส่ง(ส่งบัญชี)'!Q412 -> 1847.87 | E35: =SUM(D32:D35) -> 38573.53 | G35: =+'agingปัจจุบันส่ง(ส่งบัญชี)'!D417 -> 0 | I35: 259 | J35: =+D35-I35 -> 1588.87
A36: =+A30+1 -> 5 | B36: สำนักงานท่าเทียบเรือประมงอ่างศิลา | J36: =+D36-I36 -> 0
C37: =+C16 -> เงินรับฝากประจำเดือนกรกฎาคม 2569 | J37: =+D37-I37 -> 0
C38: ค่าเช่าอาคารและที่ดิน | D38: =+'agingปัจจุบันส่ง(ส่งบัญชี)'!Q863 -> 0 | I38: 9000
C39: รายได้เบ็ดเตล็ด(ค่ารักษามิเตอร์) | D39: =+'agingปัจจุบันส่ง(ส่งบัญชี)'!Q1346 -> 64.2 | I39: 898.8 | J39: =+D39-I39 -> -834.6
C40: ค่าประกันอัคคีภัย | D40: =+'agingปัจจุบันส่ง(ส่งบัญชี)'!Q1400 -> 1314 | I40: 1314 | L40: 2897.6
...

Sheet agingปัจจุบันส่ง(ส่งบัญชี)
A1: องค์การสะพานปลา | N1: สป.กท และ สป.สป | O1: ยอดก่อนภาษี
A2: รายละเอียดหนี้ค้างชำระค่าเช่าและค่าธรรมเนียมต่าง ๆ | N2: ค้างไม่เกิน ปี | O2: ค้างเกินปี | S2: หนี้เกิน 12 เดือน
A3: ณ วันที่ 31 กรกฎาคม 2569 | N3: หนี้ที่เกิดขึ้นระหว่าง พค.55-เมย.56 จะต้องแยกเป็นหนี้ 12 เดือน และ12 เดือนขึ้นไป | S3: สำรอง % | T3: 1 | U3: พิพากษา | V3: อยู่ระหว่างดำเนินคดี
D4: เงินรับ | F4: ค้างชำระ 1-12 เดือน | H4: ค้างชำระ 12 เดือนขึ้นไป | K4: การตั้งสำรอง | M4: สง | N4: พค.63-เมย.64 | Q4: รับล่วงหน้า
A5: ลำดับ | B5: รายชื่อ | C5: สถานที่ตั้ง | D5: ล่วงหน้า | E5: ตั้งแต่ | F5: เดือน | G5: จำนวนเงิน | H5: ตั้งแต่ | I5: เดือน | J5: จำนวนเงิน | K5: อายุหนี้ 1 วันไม่เกิน 1 ปี | L5: อายุหนี้เกิน 1 ปีขึ้นไป | S5: เปลี่ยนทุกเดือนโดยเอาเดือนที่ทำรายงานเป็นหลัก
B6: ส่วนกลาง
O7: ไม่ต้องทำอะไร
C9: รวมเป็นเงินทั้งสิ้น | G9: =SUM(G6:G8) -> 0 | J9: =SUM(J6:J8) -> 0 | N9: =+J9 -> 0
B10: สำนักงานสะพานปลากรุงเทพ
B11: ค่าเช่าอาคารและที่ดิน
A12: 1 | B12: บ.สหไทยการประมง จก | C12: แพทะเล 125 | H12: ศาลอุทธรณ์ | J12: 133272 | K12: =G12*11.54/100 -> 0 | L12: =+J12 -> 133272 | U12: =+L12 -> 133272
A13: =+A12+1 -> 2 | B13: บ.ไทยนำการประมง จำกัด | C13: อาคาร 121 | H13: ศาลอุทธรณ์ 4 ธ.ค.2558 | J13: 156061.6 | K13: =G13*11.54/100 -> 0 | L13: =+J13 -> 156061.6 | U13: =+L13 -> 156061.6
A14: 3 | B14: บ.ศิริพงศ์การประมง(1999) จำกัด | C14: อาคาร 119 | H14: ศาลแขวงพระนครใต้ 16 มิ.ย.2557 | J14: 138783.39 | K14: =G14*11.54/100 -> 0 | L14: =+J14 -> 138783.39 | U14: =+L14 -> 138783.39
A15: 4 | B15: บ.บุญชัยการประมง จำกัด | C15: อาคารแพปลา 147 | H15: ศาลฏีกา 21 กค.2559 | J15: 50000 | K15: =G15*11.54/100 -> 0 | L15: =+J15 -> 50000 | U15: =+L15 -> 50000
B16: คำพิพากษา ศาลฎีกา วันที่ 21 กค.2559 ที่ 5116/2559 | K16: =G16*11.54/100 -> 0 | L16: =+J16 -> 0
A17: 5 | B17: บ.เมธีประมงวณิช จำกัด | C17: อาคาร 113 | H17: ศาลแขวงธนบุรี 4 กย.2562 | J17: 146658.26 | K17: =G17*11.54/100 -> 0 | L17: =+J17 -> 146658.26 | U17: =+L17 -> 146658.26
A18: 6 | B18: บ.ไทยเสรีการประมง จำกัด | C18: อาคาร 139 | H18: ศาลอุทธรณ์ 28 ส.ค.2558 | J18: 137200 | K18: =G18*11.54/100 -> 0 | L18: =+J18 -> 137200 | U18: =+L18 -> 137200
B19: คำพิพากษา ศาลอุทธรณ์ วันที่ 28 สค.2558 คดีหมายเลขดำที่ ผบ.650/2558 คดีหมายเลขแดงที่ 13470/2558 | K19: =G19*11.54/100 -> 0 | L19: =+J19 -> 0
A20: 7 | B20: บ.เลาห์เรณู จำกัด | C20: อาคาร 127 | H20: ศาลอุทธรณ์ | J20: 27215 | K20: =G20*11.54/100 -> 0 | L20: =+J20 -> 27215 | P20: มูลค่าหนี้ = ยอดหนี้ตามความเป็นจริงของลูกหนี้ | U20: =+L20 -> 27215
B21: คำพิพากษา ศาลอุทธรณ์ วันที่ 20 มค.2556 คดีหมายเลขดำที่ 2025/2555 คดีหมายเลขแดงที่ 189/2556 | K21: =G21*11.54/100 -> 0 | L21: =+J21 -> 0
A22: =+A20+1 -> 8 | B22: บ.เมธีประมงวณิช จำกัด | C22: อาคาร อย.20,21 | H22: ศาลอุทธรณ์ 15 กย.2557 | J22: 665861.9 | K22: =G22*11.54/100 -> 0 | L22: =+J22 -> 665861.9 | U22: =+L22 -> 665861.9
B23: คำพิพากษา ศาลอุทธรณ์ วันที่ 15 กย.2557 คดีหมายเลขดำที่ ผบ.607/2557 คดีหมายเลขแดงที่ 16779/2557 | K23: =G23*11.54/100 -> 0 | L23: =+J23 -> 0
A24: 9 | B24: บ.พัฒนาการประมง จำกัด | C24: อาคารแพปลา | H24: ศาลฎีกา 6 มิย.2561 | J24: 103702 | K24: =G24*11.54/100 -> 0 | L24: =+J24 -> 103702 | U24: =+L24 -> 103702
B25: คำพิพากษา ศาลฎีกา วันที่ 6 มิย.2561 ที่ 4921/2560 | K25: =G25*11.54/100 -> 0 | L25: =+J25 -> 0
A26: 10 | B26: บ.บุญชัยการประมง จก | C26: ในห้อง อย. | H26: ศาลอุทธรณ์ | J26: 749484 | K26: =G26*11.54/100 -> 0 | L26: =+J26 -> 749484 | U26: =+L26 -> 749484
B27: คำพิพากษา ศาลอุทธรณ์ วันที่ 10 มิย.2558 คดีหมายเลขดำที่ ผบ.1161/2557 คดีหมายเลขแดงที่ 8339/2558 | K27: =G27*11.54/100 -> 0 | L27: =+J27 -> 0
A28: 11 | B28: บ.ไทยเสรีการประมง จำกัด | C28: ในห้อง อย. | H28: อุทธรณ์ 10 มิย.2558 | J28: 163231.6 | K28: =G28*11.54/100 -> 0 | L28: =+J28 -> 163231.6 | U28: =+L28 -> 163231.6
B29: คำพิพากษา ศาลอุทธรณ์ วันที่ 10 มิย.2558 คดีหมายเลขดำที่ ผบ.1032/2557 คดีหมายเลขแดงที่ 8334/2558 | K29: =G29*11.54/100 -> 0 | L29: =+J29 -> 0
A30: 12 | B30: บ.เลาห์เรณู จก | C30: ในห้อง อย. | H30: ศาลอุทธรณ์ 29 ส.ค.2557 | J30: 47745.65 | K30: =G30*11.54/100 -> 0 | L30: =+J30 -> 47745.65 | U30: =+L30 -> 47745.65
B31: คำพิพากษา ศาลอุทธรณ์ วันที่ 29 สค.2557 คดีหมายเลขดำที่ ผบ.456/2557 คดีหมายเลขแดงที่ 15974/2557 | K31: =G31*11.54/100 -> 0 | L31: =+J31 -> 0
A32: =+A30+1 -> 13 | B32: นส.ภารดี/ธัญยธรณ์ บวรวิชัยวัฒน์ | C32: ในห้อง อย. | H32: ศาลแพ่งกรุงเทพใต้ | J32: 287744.4 | K32: =G32*11.54/100 -> 0 | L32: =+J32 -> 287744.4 | U32: =+L32 -> 287744.4
A33: =+A32+1 -> 14 | B33: บ.บุญชัยการประมง จำกัด | C33: อาคารสนง.ริมน้ำ | H33: ศาลอุทธรณ์ 29 กค.2558 | J33: 40000 | K33: =G33*11.54/100 -> 0 | L33: =+J33 -> 40000 | U33: =+L33 -> 40000
B34: คำพิพากษา ศาลอุทธรณ์ วันที่ 29 กค.2558 คดีหมายเลขดำที่ ผบ.444/2558 คดีหมายเลขแดงที่ 11982/2558 | K34: =G34*11.54/100 -> 0 | L34: =+J34 -> 0
A35: =+A33+1 -> 15 | B35: บ.บุญชัยการประมง จก | C35: โรงประมูลปลาทะเล | H35: ศาลอุทธรณ์ | J35: 255600 | K35: =G35*11.54/100 -> 0 | L35: =+J35 -> 255600 | U35: =+L35 -> 255600
A36: =+A35+1 -> 16 | B36: บ.ประมงไทย จก | C36: โรงประมูลปลาทะเล | H36: ศาลอุทธรณ์ | J36: 64830 | K36: =G36*11.54/100 -> 0 | L36: =+J36 -> 64830 | U36: =+L36 -> 64830
B37: คำพิพากษา ศาลอุทธรณ์ วันที่ 13 มค.2559 คดีหมายเลขดำที่ ผบ.1058/2558 คดีหมายเลขแดงที่ 439/2559 | K37: =G37*11.54/100 -> 0 | L37: =+J37 -> 0
A38: =+A36+1 -> 17 | B38: บ.เมธีประมงวณิช จำกัด | C38: โรงประมูล | H38: ศาลอุทธรณ์ | J38: 175873.46 | K38: =G38*11.54/100 -> 0 | L38: =+J38 -> 175873.46 | U38: =+L38 -> 175873.46
A39: =+A38+1 -> 18 | B39: บ.เลาห์เรณู จก | C39: โรงประมูลปลาทะเล | H39: ศาลอุทธรณ์ 29 ก.ค.2558 | J39: 231163.04 | K39: =G39*11.54/100 -> 0 | L39: =+J39 -> 231163.04 | U39: =+L39 -> 231163.04
A40: =+A39+1 -> 19 | B40: บ.สหไทยการประมง จก | C40: โรงประมูลปลาทะเล | H40: ศาลฎีกา | J40: 195874.5 | K40: =G40*11.54/100 -> 0 | L40: =+J40 -> 195874.5 | U40: =+L40 -> 195874.5
A41: =+A40+1 -> 20 | B41: บ.ไทยนำการประมง จก | C41: โรงประมูลปลาทะเล | H41: ศาลอุทธรณ์ | J41: 241631.01 | K41: =G41*11.54/100 -> 0 | L41: =+J41 -> 241631.01 | U41: =+L41 -> 241631.01
...

Sheet 5.เปรียบเทียบลูกหนี้การค้า  ใหม
A1: สรุปรายงานเปรียบเทียบลูกหนี้การค้า
A2: =+'agingปัจจุบันส่ง(ส่งบัญชี)'!A3 -> ณ วันที่ 31 กรกฎาคม 2569 | H2: รายได้ (อัตรา/ | I2: ตั้งสำรอง(ประจำเดือน) | J2: ตั้งสำรอง(ประจำเดือน) | K2: ตั้งสำรอง(ประจำเดือน) | L2: ตั้งสำรอง(ประจำเดือน) | M2: ตั้งสำรอง(ประจำเดือน) | N2: ตั้งสำรอง(ประจำเดือน) | O2: ตั้งสำรอง(ประจำเดือน) | P2: ตั้งสำรอง(ประจำเดือน) | Q2: ตั้งสำรอง(ประจำเดือน) | R2: ตั้งสำรอง(ประจำเดือน) | S2: ตั้งสำรอง(ประจำเดือน) | T2: ตั้งสำรอง(ประจำเดือน) | U2: ตั้งสำรอง(ประจำเดือน) | AG2: เพิ่ม (ลด) เดือนก่อน
A3: สป./ทร. ที่มีลูกหนี้ค้างชำระ มีดังนี้ :- | B3: ก.ค.69 | C3: มิ.ย.69 | D3: สูง/ต่ำกว่าเดือนก่อน | E3: เพิ่ม(ลด) % | F3: หมายเหตุ | H3: เดือน ตค. (รายงาน) | I3: ปีจจุบัน(TFRS9) | J3: เม.ย.66 (TFRS9) | K3: มีค.66 (TFRS9) | L3: กพ.66 (TFRS9) | M3: มค.66 (TFRS9) | N3: ธค.65 (TFRS9) | O3: พย.65 (TFRS9) | P3: ตค.65 (TFRS9) | Q3: กย.65 (TFRS9) | R3: สค.65 (TFRS9) | S3: กค.65 (TFRS9) | T3: มิย.65 (TFRS9) | U3: พค.65 (TFRS9) | V3: เมย.65 | W3: มีค.65 | X3: กพ.65 | Y3: มค.65 | Z3: ธค.64 | AA3: พย.64 | AB3: ตค.64 | AC3: กย.64 | AD3: สค.64 | AE3: กค.64 | AF3: มิย.64
A4: 1. สะพานปลากรุงเทพ | B4: =+'ปะหน้าAgingรายงานหนี้ค้าง บช.'!E23 -> 28997041 | C4: 28420143 | D4: =+B4-C4 -> 576898.06 | E4: =D4/C4*100 -> 2.0298915 | F4: ** | I4: =+'agingปัจจุบันส่ง(ส่งบัญชี)'!L259+'agingปัจจุบันส่ง(ส่งบัญชี)'!K259 -> 25778593 | J4: 25520136 | K4: 25076104 | M4: 25253110 | N4: 25155469 | O4: 25133750 | P4: 25161766 | Q4: 25668618 | R4: 25052415 | S4: 25056140 | T4: 25077273 | U4: 25088841 | V4: 25091319 | W4: 25149822 | X4: 24985522 | Y4: 25024208 | AA4: 24729771 | AB4: 24575728 | AC4: 24359217 | AD4: 24160371 | AE4: 24014139 | AF4: 23596172 | AG4: =+I4-AE4 -> 1764453.9
A5: 2. สะพานปลาสมุทรปราการ | B5: =+'ปะหน้าAgingรายงานหนี้ค้าง บช.'!E37 -> 1098270.5 | C5: 1162690.6 | D5: =+B5-C5 -> -64420.14 | E5: =D5/C5*100 -> -5.540609 | I5: =+'agingปัจจุบันส่ง(ส่งบัญชี)'!L353+'agingปัจจุบันส่ง(ส่งบัญชี)'!K353 -> 1011139.2 | J5: 1059951.9 | K5: 1015197.8 | M5: 1002126.9 | N5: 1003543.2 | O5: 1001473.2 | P5: 1001246.6 | Q5: 1001246.6 | R5: 1006565.2 | S5: 1009315.6 | T5: 1007275.2 | U5: 1005602 | V5: 999772.59 | W5: 999772.59 | X5: 999772.59 | Y5: 999772.59 | AA5: 999772.59 | AB5: 999772.59 | AC5: 999772.59 | AD5: 999772.59 | AE5: 999772.59 | AF5: 999772.59 | AG5: =+I5-AE5 -> 11366.653
A6: 3. สะพานปลาสมุทรสาคร | B6: =+'ปะหน้าAgingรายงานหนี้ค้าง บช.'!E46 -> 0 | C6: 0 | D6: =+B6-C6 -> 0 | E6: 0 | I6: =+'agingปัจจุบันส่ง(ส่งบัญชี)'!J373+'agingปัจจุบันส่ง(ส่งบัญชี)'!K373 -> 0 | J6: 0 | K6: 0 | M6: 0 | N6: 0 | O6: 0 | P6: 0 | Q6: 0 | R6: 0 | S6: 0 | T6: 0 | U6: 0 | V6: 0 | W6: 0 | X6: 0 | Y6: 0 | AA6: 0 | AB6: 0 | AC6: 0 | AD6: 0 | AE6: 0 | AF6: 0 | AG6: =+I6-AE6 -> 0
A7: 4. ท่าเทียบเรือประมงตราด | B7: =+'ปะหน้าAgingรายงานหนี้ค้าง บช.'!E57 -> 3327.7 | C7: 3306.3 | D7: =+B7-C7 -> 21.4 | E7: =D7/C7*100 -> 0.64724919 | I7: =+'agingปัจจุบันส่ง(ส่งบัญชี)'!J417+'agingปัจจุบันส่ง(ส่งบัญชี)'!K417 -> 384.01658 | J7: 0 | K7: 0 | M7: 0 | N7: 0 | O7: 0 | P7: 0 | Q7: 0 | R7: 0 | S7: 401.8 | T7: 49.651 | U7: 464.5956 | V7: 0 | W7: 0 | X7: 0 | Y7: 0 | AA7: 0 | AB7: 0 | AC7: 0 | AD7: 0 | AE7: 0 | AF7: 0 | AG7: =+I7-AE7 -> 384.01658
A8: 5. ท่าเทียบเรือประมงอ่างศิลา | B8: =+'ปะหน้าAgingรายงานหนี้ค้าง บช.'!E68 -> 15361562 | C8: 15320593 | D8: =+B8-C8 -> 40969.202 | E8: =D8/C8*100 -> 0.26741265 | I8: =+'agingปัจจุบันส่ง(ส่งบัญชี)'!J418+'agingปัจจุบันส่ง(ส่งบัญชี)'!K418 -> 0 | J8: 1564415.1 | K8: 1311154.9 | M8: 139403.96 | N8: 124383.01 | O8: 109742.96 | P8: 89727.178 | Q8: 80254.734 | R8: 78288.351 | S8: 64697.764 | T8: 51201.954 | U8: 35801.097 | V8: 0 | W8: 0 | X8: 0 | Y8: 0 | AA8: 0 | AB8: 0 | AC8: 0 | AD8: 0 | AE8: 0 | AF8: 0 | AG8: =+I8-AE8 -> 0
A9: 6. ท่าเทียบเรือประมงหัวหิน | B9: =+'ปะหน้าAgingรายงานหนี้ค้าง บช.'!E77 -> 0 | C9: 0 | D9: =+B9-C9 -> 0 | E9: 0 | F9: * | I9: =+'agingปัจจุบันส่ง(ส่งบัญชี)'!L1588+'agingปัจจุบันส่ง(ส่งบัญชี)'!K1588 -> 15214323 | J9: 62673.63 | K9: 62673.63 | M9: 62673.63 | N9: 62673.63 | O9: 62673.63 | P9: 62673.63 | Q9: 62673.63 | R9: 62673.63 | S9: 62673.63 | T9: 62673.63 | U9: 654273.63 | V9: 654273.63 | W9: 654273.63 | X9: 654273.63 | Y9: 654273.63 | AA9: 654273.63 | AB9: 654273.63 | AC9: 658335.02 | AD9: 6358735 | AE9: 6362735 | AF9: 6366735 | AG9: =+I9-AE9 -> 8851587.7
A10: 7. ท่าเทียบเรือประมงชุมพร | B10: =+'ปะหน้าAgingรายงานหนี้ค้าง บช.'!E94 -> 541726.78 | C10: 545219.24 | D10: =+B10-C10 -> -3492.46 | E10: =D10/C10*100 -> -0.64056067 | I10: =+'agingปัจจุบันส่ง(ส่งบัญชี)'!L1648+'agingปัจจุบันส่ง(ส่งบัญชี)'!K1648 -> 435681.57 | J10: 193299.24 | K10: 174046.36 | M10: 74289.964 | N10: 75541.653 | O10: 65695.241 | P10: 61043.095 | Q10: 38136.873 | R10: 95369.178 | S10: 78956.437 | T10: 91138.496 | U10: 117675.6 | V10: 171380 | W10: 194880 | X10: 163320 | Y10: 154450 | AA10: 89260 | AB10: 57600 | AC10: 28500 | AD10: 23400 | AE10: 18300 | AF10: 11040 | AG10: =+I10-AE10 -> 417381.57
A11: 8. ท่าเทียบเรือประมงหลังสวน | B11: =+'ปะหน้าAgingรายงานหนี้ค้าง บช.'!E100 -> 0 | C11: 0 | D11: =+B11-C11 -> 0 | E11: 0 | I11: =+'agingปัจจุบันส่ง(ส่งบัญชี)'!L1658+'agingปัจจุบันส่ง(ส่งบัญชี)'!K1658 -> 0 | J11: 288906.02 | K11: 288906.02 | M11: 288906.02 | N11: 288906.02 | O11: 288906.02 | P11: 288906.02 | Q11: 289173.96 | R11: 288921.37 | S11: 288906.02 | T11: 289138.64 | U11: 288906.02 | V11: 288906.02 | W11: 288906.02 | X11: 288906.02 | Y11: 288906.02 | AA11: 288906.02 | AB11: 288906.02 | AC11: 288906.02 | AD11: 288906.02 | AE11: 288906.02 | AF11: 288906.02 | AG11: =+I11-AE11 -> -288906.02
A12: 9. ท่าเทียบเรือประมงสุราษฎร์ธานี | B12: =+'ปะหน้าAgingรายงานหนี้ค้าง บช.'!E110 -> 5530855.9 | C12: 5530855.9 | D12: =+B12-C12 -> 0 | E12: =D12/C12*100 -> 0 | I12: =+'agingปัจจุบันส่ง(ส่งบัญชี)'!L1675+'agingปัจจุบันส่ง(ส่งบัญชี)'!K1675 -> 5530855.9 | J12: 5531153.3 | K12: 5531153.3 | M12: 5530855.9 | N12: 5531077.4 | O12: 5531313.6 | P12: 5530888.3 | Q12: 5531061.8 | R12: 5531196.3 | S12: 5531336.6 | T12: 5531879.5 | U12: 5531711.7 | V12: 5530855.9 | W12: 5530855.9 | X12: 5530855.9 | Y12: 5530855.9 | AA12: 5530855.9 | AB12: 5530855.9 | AC12: 5530855.9 | AD12: 5530855.9 | AE12: 5530855.9 | AF12: 5530855.9 | AG12: =+I12-AE12 -> 0
A13: 10. สะพานปลานครศรีธรรมราช | B13: =+'ปะหน้าAgingรายงานหนี้ค้าง บช.'!E119 -> 13895.52 | C13: 13125.95 | D13: =+B13-C13 -> 769.57 | E13: =D13/C13*100 -> 5.8629661 | I13: =+'agingปัจจุบันส่ง(ส่งบัญชี)'!L1707+'agingปัจจุบันส่ง(ส่งบัญชี)'!K1707 -> 10810.902 | J13: 3249.1097 | K13: 12365.085 | M13: 11751.927 | N13: 11741.201 | O13: 12012.975 | P13: 11741.753 | Q13: 11716.662 | R13: 12015.987 | S13: 12018.75 | T13: 12052.715 | U13: 12046.903 | V13: 11988.5 | W13: 11988.5 | X13: 11988.5 | Y13: 12488.4 | AA13: 10452.5 | AB13: 10452.5 | AC13: 10452.5 | AD13: 10452.5 | AE13: 10452.5 | AF13: 10452.5 | AG13: =+I13-AE13 -> 358.40211
A14: 11. ท่าเทียบเรือประมงสงขลา | B14: =+'ปะหน้าAgingรายงานหนี้ค้าง บช.'!E123 -> 0 | C14: 0 | D14: =+B14-C14 -> 0 | E14: 0 | I14: =+'agingปัจจุบันส่ง(ส่งบัญชี)'!J1712 -> 0 | J14: 0 | K14: 0 | M14: 0 | N14: 0 | O14: 0 | P14: 0 | Q14: 0 | R14: 0 | S14: 0 | T14: 0 | U14: 0 | V14: 0 | W14: 0 | X14: 0 | Y14: 0 | AA14: 0 | AB14: 0 | AC14: 0 | AD14: 0 | AE14: 0 | AF14: 0 | AG14: =+I14-AE14 -> 0
A15: 12. ท่าเทียบเรือประมงสงขลา(ท่าสะอ้าน) | B15: =+'ปะหน้าAgingรายงานหนี้ค้าง บช.'!E140 -> 659103.34 | C15: 737830.6 | D15: =+B15-C15 -> -78727.26 | E15: =D15/C15*100 -> -10.6701 | I15: =+'agingปัจจุบันส่ง(ส่งบัญชี)'!L1861+'agingปัจจุบันส่ง(ส่งบัญชี)'!K1861 -> 535605.06 | J15: 506382.23 | K15: 574924.3 | M15: 552560.18 | N15: 555218.16 | O15: 555471.59 | P15: 578591.95 | Q15: 572696.39 | R15: 577067.49 | S15: 583888.13 | T15: 581019.95 | U15: 585600.5 | V15: 581053.69 | W15: 584545.15 | X15: 637374.45 | Y15: 649449.23 | AA15: 656117.78 | AB15: 659754.83 | AC15: 662923.38 | AD15: 674982.1 | AE15: 681341.25 | AF15: 684370.15 | AG15: =+I15-AE15 -> -145736.19
A16: 13. ท่าเทียบเรือประมงระนอง | B16: =+'ปะหน้าAgingรายงานหนี้ค้าง บช.'!E154 -> 9071978.7 | C16: 9089040.3 | D16: =+B16-C16 -> -17061.582 | E16: =D16/C16*100 -> -0.18771599 | I16: =+'agingปัจจุบันส่ง(ส่งบัญชี)'!J1944+'agingปัจจุบันส่ง(ส่งบัญชี)'!K1944 -> 9047521.5 | J16: 8724187.3 | K16: 8681045.8 | M16: 8653076.2 | N16: 8652004.2 | O16: 8647785.7 | P16: 8651431 | Q16: 8647758.6 | R16: 8647950.2 | S16: 8649178.1 | T16: 8648563.7 | U16: 8654352.4 | V16: 8647209.9 | W16: 8647209.9 | X16: 8654084.6 | Y16: 8656973.6 | AA16: 8656973.6 | AB16: 8656973.6 | AC16: 8656973.6 | AD16: 8656224.6 | AE16: 8640651.5 | AF16: 8613470.9 | AG16: =+I16-AE16 -> 406870.02
A17: 14. ท่าเทียบเรือประมงปัตตานี | B17: =+'ปะหน้าAgingรายงานหนี้ค้าง บช.'!E169 -> 2195801.7 | C17: 2538148.8 | D17: =+B17-C17 -> -342347.05 | E17: =D17/C17*100 -> -13.488061 | I17: =+'agingปัจจุบันส่ง(ส่งบัญชี)'!L2851+'agingปัจจุบันส่ง(ส่งบัญชี)'!L2820 -> 1658078.5 | J17: 707065.5 | K17: 853966.21 | M17: 666673.18 | N17: 668858.59 | O17: 628962.7 | P17: 707284.3 | Q17: 843090.7 | R17: 862864.6 | S17: 667954.92 | T17: 643237.05 | U17: 729917.89 | V17: 642686.31 | W17: 607134.84 | X17: 313964.95 | Y17: 222374.09 | AA17: 177269.62 | AB17: 157157 | AC17: 126105 | AD17: 116665 | AE17: 97975 | AF17: 83845 | AG17: =+I17-AE17 -> 1560103.5
A18: 15. ท่าเทียบเรือประมงนราธิวาส | B18: =+'ปะหน้าAgingรายงานหนี้ค้าง บช.'!E176 -> 683300 | C18: 685500 | D18: =+B18-C18 -> -2200 | E18: =D18/C18*100 -> -0.32093363 | I18: =+'agingปัจจุบันส่ง(ส่งบัญชี)'!L2894+'agingปัจจุบันส่ง(ส่งบัญชี)'!K2894 -> 683300 | J18: 914946.35 | K18: 916946.35 | M18: 938888.97 | N18: 938888.97 | O18: 938888.97 | P18: 938888.97 | Q18: 939388.97 | R18: 939888.97 | S18: 940388.97 | T18: 940888.97 | U18: 942206.19 | V18: 942300 | W18: 932900 | X18: 913000 | Y18: 908400 | AA18: 899400 | AB18: 892100 | AC18: 890500 | AD18: 883400 | AE18: 881900 | AF18: 875100 | AG18: =+I18-AE18 -> -198600
A19: 16. ท่าเทียบเรือประมงภูเก็ต | B19: =+'ปะหน้าAgingรายงานหนี้ค้าง บช.'!E193 -> 1734600.9 | C19: 1689069.4 | D19: =+B19-C19 -> 45531.578 | E19: =D19/C19*100 -> 2.6956606 | I19: =+'agingปัจจุบันส่ง(ส่งบัญชี)'!L3008+'agingปัจจุบันส่ง(ส่งบัญชี)'!K3008 -> 1433839.9 | J19: 4981697.3 | K19: 5010377.5 | M19: 4791644.5 | N19: 4588744.8 | O19: 4598698.9 | P19: 4618591.8 | Q19: 4652815.4 | R19: 4615611.4 | S19: 4698608.5 | T19: 4591700 | U19: 4584198 | V19: 3950544.6 | W19: 3861576.7 | X19: 2969356.7 | Y19: 2866695.2 | AA19: 2694442.4 | AB19: 2617941.7 | AC19: 2506912.6 | AD19: 2298704.5 | AE19: 2189618.1 | AF19: 2073703.1 | AG19: =+I19-AE19 -> -755778.25
A20: 17. ท่าเทียบเรือประมงสตูล | B20: =+'ปะหน้าAgingรายงานหนี้ค้าง บช.'!E205 -> 878713.26 | C20: 866633.26 | D20: =+B20-C20 -> 12080 | E20: =D20/C20*100 -> 1.3938999 | F20: *** | I20: =+'agingปัจจุบันส่ง(ส่งบัญชี)'!L3064+'agingปัจจุบันส่ง(ส่งบัญชี)'!K3064 -> 816242.81 | J20: 470030.9 | K20: 483479.57 | M20: 458433.59 | N20: 455097.36 | O20: 453223.39 | P20: 452818.42 | Q20: 453184.69 | R20: 454894.07 | S20: 455777.1 | T20: 452501.72 | U20: 452220.03 | V20: 450554.8 | W20: 449054.8 | X20: 735369.8 | Y20: 744154.8 | AA20: 738349.8 | AB20: 746149.8 | AC20: 743314.8 | AD20: 663879.8 | AE20: 661044.8 | AF20: 663444.8 | AG20: =+I20-AE20 -> 155198.01
A21: รวม | B21: =SUM(B4:B20) -> 66770177 | C21: =SUM(C4:C20) -> 66602156 | D21: =SUM(D4:D20) -> 168021.32 | E21: =+D21/C21*100 -> 0.25227609 | H21: =SUM(H4:H20) -> 0 | I21: =SUM(I4:I20) -> 62156375 | J21: =SUM(J4:J20) -> 50528094 | K21: =SUM(K4:K20) -> 49992340 | M21: =SUM(M4:M20) -> 48424395 | N21: =SUM(N4:N20) -> 48112147 | O21: =SUM(O4:O20) -> 48028599 | P21: =SUM(P4:P20) -> 48155599 | Q21: =SUM(Q4:Q20) -> 48791817 | R21: =SUM(R4:R20) -> 48225721 | S21: =SUM(S4:S20) -> 48100242 | T21: =SUM(T4:T20) -> 47980594 | U21: =SUM(U4:U20) -> 48683818 | V21: 47962844 | W21: =SUM(W4:W20) -> 47912920 | X21: =SUM(X4:X20) -> 46857789 | Y21: =SUM(Y4:Y20) -> 46713001 | Z21: =SUM(Z4:Z20) -> 0 | AA21: =SUM(AA4:AA20) -> 46125845 | AB21: =SUM(AB4:AB20) -> 45847665 | AC21: =SUM(AC4:AC20) -> 45462768 | AD21: =SUM(AD4:AD20) -> 50666349 | ... AF21: =SUM(AF4:AF20) -> 49797868 | AG21: =+I21-AE21 -> 11778683
A22: หมายเหตุ : เดือน พ.ค. 64 สบน. ปรับยอดหนี้ให้เป็นไปตามคำพิพากษาฎีกาและศาลอุทธรณ์ จากลูกหนี้ | E22: =+D22/C22*100 -> #DIV/0!
A23: หมายเหตุ : ข้อมูลตัวเลขจากสป.ทร.ต่างๆ | E23: =+D23/C23*100 -> #DIV/0! | I23: =+'agingปัจจุบันส่ง(ส่งบัญชี)'!L3069 -> 62218428 | M23: =+M21-N21 -> 312248.3 | N23: =+N21-O21 -> 83547.667 | T23: =+I21-T21 -> 14175781
A24: เดือน | D24: =+'agingปัจจุบันส่ง(ส่งบัญชี)'!#REF! -> #REF! | E24: =+D24/C24*100 -> #REF! | I24: =+I21-M21 -> 13731979 | Q24: 48225721 | W24: =+I21-W21 -> 14243455
A25: มติคอก.ครั้งที่ 10/2561 เมื่อวันที่ 19 ต.ค.2561 (ได้ปรับลดยอดหนี้ให้เป็นตามมติ คกอ. ในเดือน ก.ย.64) | E25: =+D25/C25*100 -> #DIV/0!
B26: =+'agingปัจจุบันส่ง(ส่งบัญชี)'!J3068-B21 -> 0 | C26: 0 | E26: =+D26/C26*100 -> #DIV/0!
A27: สป.กท. ในส่วนที่อยู่ในที่ดิน อสป. เช่าสำนักงานทรัพย์สินส่วนพระมหากษัตริย์ | E27: =+D27/C27*100 -> #DIV/0!
E28: =+D28/C28*100 -> #DIV/0!
E29: =+D29/C29*100 -> #DIV/0!
E30: =+D30/C30*100 -> #DIV/0! | G30: %คิดจาก เดือนที่แล้ว-เดือนปจด. =ผลต่าง*100/เดือนที่แล้ว
E31: =+D31/C31*100 -> #DIV/0!
E32: =+D32/C32*100 -> #DIV/0! | G32: =+C21-B21 -> -168021.32
E33: =+D33/C33*100 -> #DIV/0! | G33: =+G32*100/C21 -> -0.25227609
E34: =+D34/C34*100 -> #DIV/0!

Sheet 4.สำรองหนี้สูญ
A1: สรุปรายงานสำรองค่าเผื่อหนี้สูญ
A2: ณ.วันที่ 31 กรกฎาคม 2569
A3: สป./ทร. ที่มีลูกหนี้ค้างชำระ มีดังนี้ :- | B3: ยอดหนี้ค้าง | C3: สำรองค่าเผื่อหนี้สูญ
C4: หนี้ 1 เดือนไม่เกิน 1 ปี | D4: หนี้เกิน 1 ปีขึ้นไป | E4: รวมสำรอง TFRS 9
A5: 1. สะพานปลากรุงเทพ | B5: =+'5.เปรียบเทียบลูกหนี้การค้า ใหม'!B4 -> 28997041 | C5: =+'agingปัจจุบันส่ง(ส่งบัญชี)'!K259 -> 419860.91 | D5: =+'agingปัจจุบันส่ง(ส่งบัญชี)'!L259 -> 25358732 | E5: =+D5+C5 -> 25778593 | F5: =+(B5-D5)*11.54/100 -> 419860.91 | G5: =+C5-F5 -> 0
A6: 2. สะพานปลาสมุทรปราการ | B6: =+'5.เปรียบเทียบลูกหนี้การค้า ใหม'!B5 -> 1098270.5 | C6: =+'agingปัจจุบันส่ง(ส่งบัญชี)'!K353 -> 11366.653 | D6: =+'agingปัจจุบันส่ง(ส่งบัญชี)'!L353 -> 999772.59 | E6: =+D6+C6 -> 1011139.2 | F6: =+(B6-D6)*11.54/100 -> 11366.653 | G6: =+C6-F6 -> 0
A7: 3. สะพานปลาสมุทรสาคร | B7: =+'5.เปรียบเทียบลูกหนี้การค้า ใหม'!B6 -> 0 | C7: =+'agingปัจจุบันส่ง(ส่งบัญชี)'!K373 -> 0 | D7: =+'agingปัจจุบันส่ง(ส่งบัญชี)'!L373 -> 0 | E7: =+D7+C7 -> 0 | F7: =+(B7-D7)*11.54/100 -> 0 | G7: =+C7-F7 -> 0
A8: 4. ท่าเทียบเรือประมงตราด | B8: =+'5.เปรียบเทียบลูกหนี้การค้า ใหม'!B7 -> 3327.7 | C8: =+'agingปัจจุบันส่ง(ส่งบัญชี)'!K417 -> 384.01658 | D8: =+'agingปัจจุบันส่ง(ส่งบัญชี)'!L417 -> 0 | E8: =+D8+C8 -> 384.01658 | F8: =+(B8-D8)*11.54/100 -> 384.01658 | G8: =+C8-F8 -> 0
A9: 5. ท่าเทียบเรือประมงอ่างศิลา | B9: =+'5.เปรียบเทียบลูกหนี้การค้า ใหม'!B8 -> 15361562 | C9: =+'agingปัจจุบันส่ง(ส่งบัญชี)'!K1588 -> 19207.984 | D9: =+'agingปัจจุบันส่ง(ส่งบัญชี)'!L1588 -> 15195115 | E9: =+D9+C9 -> 15214323 | F9: =+(B9-D9)*11.54/100 -> 19207.984 | G9: =+C9-F9 -> 0
A10: 6. ท่าเทียบเรือประมงหัวหิน | B10: =+'5.เปรียบเทียบลูกหนี้การค้า ใหม'!B9 -> 0 | C10: =+'agingปัจจุบันส่ง(ส่งบัญชี)'!K1598 -> 0 | D10: =+'agingปัจจุบันส่ง(ส่งบัญชี)'!L1598 -> 0 | E10: =+D10+C10 -> 0 | F10: =+(B10-D10)*11.54/100 -> 0 | G10: =+C10-F10 -> 0
A11: 7. ท่าเทียบเรือประมงชุมพร | B11: =+'5.เปรียบเทียบลูกหนี้การค้า ใหม'!B10 -> 541726.78 | C11: =+'agingปัจจุบันส่ง(ส่งบัญชี)'!K1648 -> 13834.069 | D11: =+'agingปัจจุบันส่ง(ส่งบัญชี)'!L1648 -> 421847.5 | E11: =+D11+C11 -> 435681.57 | F11: =+(B11-D11)*11.54/100 -> 13834.069 | G11: =+C11-F11 -> 0 | K11: 60641836
A12: 8. ท่าเทียบเรือประมงหลังสวน | B12: =+'5.เปรียบเทียบลูกหนี้การค้า ใหม'!B11 -> 0 | C12: =+'agingปัจจุบันส่ง(ส่งบัญชี)'!K1658 -> 0 | D12: =+'agingปัจจุบันส่ง(ส่งบัญชี)'!L1658 -> 0 | E12: =+D12+C12 -> 0 | F12: =+(B12-D12)*11.54/100 -> 0 | G12: =+C12-F12 -> 0 | K12: 56713050
A13: 9. ท่าเทียบเรือประมงสุราษฎร์ธานี | B13: =+'5.เปรียบเทียบลูกหนี้การค้า ใหม'!B12 -> 5530855.9 | C13: =+'agingปัจจุบันส่ง(ส่งบัญชี)'!K1675 -> 0 | D13: =+'agingปัจจุบันส่ง(ส่งบัญชี)'!L1675 -> 5530855.9 | E13: =+D13+C13 -> 5530855.9 | F13: =+(B13-D13)*11.54/100 -> 0 | G13: =+C13-F13 -> 0
A14: 10. สะพานปลานครศรีธรรมราช | B14: =+'5.เปรียบเทียบลูกหนี้การค้า ใหม'!B13 -> 13895.52 | C14: =+'agingปัจจุบันส่ง(ส่งบัญชี)'!K1707 -> 402.40211 | D14: =+'agingปัจจุบันส่ง(ส่งบัญชี)'!L1707 -> 10408.5 | E14: =+D14+C14 -> 10810.902 | F14: =+(B14-D14)*11.54/100 -> 402.40211 | G14: =+C14-F14 -> 0 | K14: =SUM(K11-K12) -> 3928785.3
A15: 11. ท่าเทียบเรือประมงสงขลา | B15: =+'5.เปรียบเทียบลูกหนี้การค้า ใหม'!B14 -> 0 | C15: =+'agingปัจจุบันส่ง(ส่งบัญชี)'!K1712 -> 0 | D15: =+'agingปัจจุบันส่ง(ส่งบัญชี)'!L1712 -> 0 | E15: =+D15+C15 -> 0 | F15: =+(B15-D15)*11.54/100 -> 0 | G15: =+C15-F15 -> 0
A16: 12. ท่าเทียบเรือประมงสงขลา(ท่าสะอ้าน) | B16: =+'5.เปรียบเทียบลูกหนี้การค้า ใหม'!B15 -> 659103.34 | C16: =+'agingปัจจุบันส่ง(ส่งบัญชี)'!K1861 -> 16110.899 | D16: =+'agingปัจจุบันส่ง(ส่งบัญชี)'!L1861 -> 519494.16 | E16: =+D16+C16 -> 535605.06 | F16: =+(B16-D16)*11.54/100 -> 16110.899 | G16: =+C16-F16 -> -2.3646862e-11
A17: 13.ท่าเทียบเรือประมงระนอง | B17: =+'5.เปรียบเทียบลูกหนี้การค้า ใหม'!B16 -> 9071978.7 | C17: =+'agingปัจจุบันส่ง(ส่งบัญชี)'!K1944 -> 3190.5472 | D17: =+'agingปัจจุบันส่ง(ส่งบัญชี)'!L1944 -> 9044331 | E17: =+D17+C17 -> 9047521.5 | F17: =+(B17-D17)*11.54/100 -> 3190.5472 | G17: =+C17-F17 -> 7.2304829e-11
A18: 14. ท่าเทียบเรือประมงปัตตานี | B18: =+'5.เปรียบเทียบลูกหนี้การค้า ใหม'!B17 -> 2195801.7 | C18: =+'agingปัจจุบันส่ง(ส่งบัญชี)'!K2851 -> 62053.261 | D18: =+'agingปัจจุบันส่ง(ส่งบัญชี)'!L2851 -> 1658078.5 | E18: =+D18+C18 -> 1720131.8 | F18: =+(B18-D18)*11.54/100 -> 62053.261 | G18: =+C18-F18 -> 2.6921043e-10
A19: 15. ท่าเทียบเรือประมงนราธิวาส | B19: =+'5.เปรียบเทียบลูกหนี้การค้า ใหม'!B18 -> 683300 | C19: =+'agingปัจจุบันส่ง(ส่งบัญชี)'!K2894 -> 0 | D19: =+'agingปัจจุบันส่ง(ส่งบัญชี)'!L2894 -> 683300 | E19: =+D19+C19 -> 683300 | F19: =+(B19-D19)*11.54/100 -> 0 | G19: =+C19-F19 -> 0
A20: 16. ท่าเทียบเรือประมงภูเก็ต | B20: =+'5.เปรียบเทียบลูกหนี้การค้า ใหม'!B19 -> 1734600.9 | C20: =+'agingปัจจุบันส่ง(ส่งบัญชี)'!K3008 -> 39235.617 | D20: =+'agingปัจจุบันส่ง(ส่งบัญชี)'!L3008 -> 1394604.3 | E20: =+D20+C20 -> 1433839.9 | F20: =+(B20-D20)*11.54/100 -> 39235.617 | G20: =+C20-F20 -> 0
A21: 17. ท่าเทียบเรือประมงสตูล | B21: =+'5.เปรียบเทียบลูกหนี้การค้า ใหม'!B20 -> 878713.26 | C21: =+'agingปัจจุบันส่ง(ส่งบัญชี)'!K3064 -> 8149.548 | D21: =+'agingปัจจุบันส่ง(ส่งบัญชี)'!L3064 -> 808093.26 | E21: =+D21+C21 -> 816242.81 | F21: =+(B21-D21)*11.54/100 -> 8149.548 | G21: =+C21-F21 -> 0
A22: รวม | B22: =SUM(B5:B21) -> 66770177 | C22: =SUM(C5:C21) -> 593795.91 | D22: =SUM(D5:D21) -> 61624632 | E22: =SUM(E5:E21) -> 62218428 | G22: =+C22-F22 -> 593795.91
A23: หมายเหตุ : เดือน พ.ค. 64 สบน. ปรับยอดหนี้ให้เป็นไปตามคำพิพากษาฎีกาและศาลอุทธรณ์ จากลูกหนี้
A24: หมายเหตุ : คิดค่าเผื่อหนี้สูญ อัตรา 20.85% (อัตราตามที่ผู้ตรวจสอบบัญชีประจำปี 2566 คำนวณ จากอัตรา
A25: 1. อัตรา GDP ปี 2564 เท่ากับ 1.5% ปี 2565 เท่ากับ 3.2% และ ปี 2566 เท่ากับ 3.7 %
A26: 2. อัตราเงินเฟ้อปี 2564 เท่ากับ 1.2% ปี 2565 เท่ากับ 6.3% และ ปี 2566 เท่ากับ 3 %
B28: สำรองค่าเผื่อหนี้สูญ เดือน ก.ค.69 | D28: =E22 -> 62218428
B29: สำรองค่าเผื่อหนี้สูญ เดือน มิ.ย.69 | D29: 62582277
C30: สูง (ต่ำ) (71,516.86) | D30: =D28-D29 -> -363848.59 | K30: =62083792.14-61815214.91 -> 268577.23
G31: =61591852.89-61402730.75 -> 189122.14

Sheet 6.รับชำระประจำเดือน
A1: รายงานรายได้ของสะพานปลาและท่าเทียบเรือประมงประจำเดือน กรกฎาคม 2568 เปรียบเทียบเดือนมิถุนายน 2568
Y2: หน่วย : บาท
A3: หน่วยงาน | B3: ประเภทการรับชำระ | AA3: เปรียบเทียบ | AB3: รับชำระ
B4: ค่าบริการ สัตว์น้ำ | C4: คธ | D4: คธ | E4: คธ | F4: คธ | G4: คธ | H4: คธ | I4: คธ | J4: ค่าเช่าที่จำหน่าย | K4: ค่าเช่าอาคาร | L4: ค่าเช่าที่ | M4: ค่าสุขาภิบาล | N4: ค่าจำหน่าย | O4: ค่าจำหน่าย | P4: ค่าต่ออายุ | Q4: ค่าเช่าสถานที่ | R4: ค่าตอบแทนเพื่อใช้ประโยชน์พื้นที่ | S4: รายได้เบ็ดเตล็ด | W4: หนี้ผ่อนชำระ | X4: หนี้บอกเลิกสัญญา | Y4: หนี้ดำเนินคดี/ | Z4: รวม | AA4: เดือน มิ.ย.2569 | AD4: งวดที่ | AE4: 7 | AF4: 12500
C5: สัตว์น้ำผ่านท่า | D5: รถผ่านท่า | E5: น้ำแข็งผ่านท่า | F5: น้ำมันผ่านท่า | G5: ใช้เครื่องชั่ง | H5: ใช้สถานที่ | I5: อื่น ๆ | J5: น้ำแข็งและ | K5: และที่ดิน | L5: อื่นๆ | N5: น่ำประปา | O5: ไฟฟ่า | P5: สัญญา/สิทธิ | Q5: จำหน่าย | S5: ภาษีโรงเรือน | T5: ประกันอัคคีภัย | U5: ค่ารักษา | V5: อื่น ๆ | Y5: พิพากษา | AA5: สูง(ต่ำ) | AD5: งวดที่ | AE5: 7 | AF5: 23000
J6: เครื่องโม่ | P6: การเช่า | Q6: น้ำมัน | U6: มิเตอร์ | AD6: งวดที่ | AE6: 7 | AF6: 22500
A7: 1. สะพานปลากรุงเทพ | K7: 586483 | L7: 50500 | N7: 15580.2 | O7: 31915.96 | P7: 30191 | W7: 2000 | Y7: 9558.39 | Z7: =SUM(B7:Y7) -> 726228.55 | AA7: 1114630.6
A8: 2. สะพานปลาสมุทรปราการ | D8: 33308 | E8: 2140 | H8: 149465 | K8: 202456.81 | M8: 10914 | N8: 15021.23 | O8: 66384.22 | P8: 3840 | S8: 16513.32 | Z8: =SUM(B8:Y8) -> 500042.58 | AA8: 528948.17
A9: 3. สะพานปลาสมุทรสาคร | D9: 1819 | L9: 27808.18 | N9: 4622.4 | O9: 11198.62 | Z9: =SUM(B9:Y9) -> 45448.2 | AA9: 48044.02
A10: 4. ตราด | C10: 3137.24 | D10: 1110 | H10: 3852 | K10: 108020.6 | L10: 16165 | O10: 26247.1 | S10: 9630 | Z10: =SUM(B10:Y10) -> 168161.94 | AA10: 182573.06
A11: 5. ท่าเทียบเรือประมงอ่างศิลา | E11: 39006.85 | H11: 60000 | K11: 440300 | N11: 44041.2 | O11: 26685.8 | R11: 51949.4 | U11: 8153.4 | W11: 12959 | Z11: =SUM(B11:Y11) -> 683095.65 | AA11: 701382.7
A12: 6. ท่าเทียบเรือประมงหัวหิน | H12: 81700 | I12: 3210 | N12: 2000 | O12: 17612.2 | Z12: =SUM(B12:Y12) -> 104522.2 | AA12: 88732
A13: 7. ท่าเทียบเรือประมงชุมพร | C13: 62374.08 | D13: 4301.4 | F13: 1177 | H13: 24503 | N13: 42372 | O13: 20197.32 | Z13: =SUM(B13:Y13) -> 154924.8 | AA13: 182501.06
A14: 8. ท่าเทียบเรือประมงหลังสวน | E14: 4601 | J14: 4630 | K14: 23640 | Z14: =SUM(B14:Y14) -> 32871 | AA14: 39436
A15: 9. ท่าเทียบเรือประมงสุราษฎร์ธานี | Z15: =SUM(B15:Y15) -> 0 | AA15: 0
A16: 10. สะพานปลานครศรีธรรมราช | E16: 1348.2 | K16: 18842 | M16: 50 | N16: 299.6 | O16: 13661.76 | Z16: =SUM(B16:Y16) -> 34201.56 | AA16: 34024.33
A17: 11. ท่าเทียบเรือประมงสงขลา | K17: 228132 | P17: 11900 | Z17: =SUM(B17:Y17) -> 240032 | AA17: 240032
A18: 12. ท่าเทียบเรือประมงสงขลา(ท่าสะอ้าน) | C18: 45113.34 | D18: 10443.2 | E18: 75405.33 | G18: 9022.67 | H18: 19107.5 | K18: 152860.5 | L18: 24845 | M18: 2750 | N18: 177611.6 | O18: 286750.4 | W18: 100 | Z18: =SUM(B18:Y18) -> 804009.54 | AA18: 622299.92
A19: 13. ท่าเทียบเรือประมงระนอง | C19: 94374.21 | D19: 10753.5 | E19: 12037.5 | F19: 2140 | H19: 521090 | K19: 201033.75 | L19: 1500 | O19: 513.6 | Q19: 66660 | Z19: =SUM(B19:Y19) -> 910102.56 | AA19: 861444.2
A20: 14. ท่าเทียบเรือประมงปัตตานี | D20: 5564 | E20: 48150 | H20: 183507.53 | J20: 42244.05 | K20: 574720.22 | L20: 241930 | M20: 56838.4 | N20: 46630.6 | O20: 6955 | P20: 218800 | X20: 2076 | Z20: =SUM(B20:Y20) -> 1427415.8 | AA20: 1431912.8
A21: 15. ท่าเทียบเรือประมงนราธิวาส | W21: 2200 | Z21: =SUM(B21:Y21) -> 2200 | AA21: 800
A22: 16. ท่าเทียบเรือประมงภูเก็ต | C22: 1958.1 | D22: 84355 | E22: 19332.23 | F22: 16050 | H22: 28355 | K22: 752476.01 | L22: 3150 | N22: 4221.15 | O22: 291040 | R22: 8400 | S22: 293959.47 | Z22: =SUM(B22:Y22) -> 1503297 | AA22: 1284238.7
A23: 17. ท่าเทียบเรือประมงสตูล | H23: 2140 | K23: 18740 | L23: 14900 | Q23: 0 | Z23: =SUM(B23:Y23) -> 35780 | AA23: 49225
Z24: =SUM(Z7:Z23) -> 7372333.3 | AA24: =SUM(AA7:AA23) -> 7410224.6
AE25: 1287080.5
T26: รวมรับชำระ ก.ค. 2569 | X26: =+Z24 -> 7372333.3 | Y26: =Z24 -> 7372333.3 | Z26: บาท
T27: เปรียบเทียบ มิ.ย.2569 | X27: =+AA24 -> 7410224.6 | Y27: =+AA24 -> 7410224.6 | Z27: บาท
T28: สูง (ต่ำ) | X28: =SUM(X26-X27) -> -37891.25 | Y28: =SUM(Y26-Y27) -> -37891.25 | Z28: บาท
AC29: =+Z24-AA24 -> -37891.25
N31: ค่าธรรมเนียมสัตว์น้ำ สป.กท.ไม่บันทึกตั้งแต่เดือน มิ.ย.69
C34: p;+

Sheet ส่งวาระ คตส.+ปะหน้า
B1: รายงานสรุปยอดหนี้ค้างชำระค่าเช่าและค่าธรรมเนียมต่าง ๆ ของ สป.ทร.
B2: เดือน กรกฎาคม 2569
E4: เดือน กรกฎาคม 2569 | G4: เดือน มิถุนายน 2569 | I4: เปรียบเทียบเดือนก่อน
C5: ลำดับ | D5: รายการ | E5: จำนวนรายการ | F5: จำนวนเงิน | G5: จำนวนรายการ | H5: จำนวนเงิน | I5: จำนวนรายการ | J5: จำนวนเงิน | K5: %
C6: 1 | D6: ยอดหนี้ลูกหนี้การค้า
D7: - รายได้อยู่ระหว่างจัดเก็บ 1-30 วัน | E7: 419 | F7: 904641.86 | G7: 359 | H7: 983968.03 | I7: =E7-G7 -> 60 | J7: =F7-H7 -> -79326.172 | K7: =J7/H7*100 -> -8.0618648
D8: - รายได้อยู่ระหว่างจัดเก็บ 30 วันไม่เกิน 60 วัน | E8: 56 | F8: 434649.48 | G8: 72 | H8: 380362.04 | I8: =E8-G8 -> -16 | J8: =F8-H8 -> 54287.44 | K8: =J8/H8*100 -> 14.27257
D9: - หนี้ค้างชำระเกิน 60 วันไม่เกิน 180 วัน | E9: 55 | F9: 530911.65 | G9: 46 | H9: 2531382 | I9: =E9-G9 -> 9 | J9: =F9-H9 -> -2000470.3 | K9: =J9/H9*100 -> -79.026806
D10: - หนี้ค้างชำระเกิน 180 วันไม่เกิน 1 ปี | E10: 29 | F10: 166919.97 | G10: 22 | H10: 83092.899 | I10: =E10-G10 -> 7 | J10: =F10-H10 -> 83827.071 | K10: =J10/H10*100 -> 100.88356
D11: รวมหนี้ค้างไม่เกิน 1 ปี | E11: =SUM(E7:E10) -> 559 | F11: =SUM(F7:F10) -> 2037123 | G11: 499 | H11: 3978805 | I11: =E11-G11 -> 60 | J11: =F11-H11 -> -1941682 | K11: =J11/H11*100 -> -48.800633
D12: - หนี้ค้างชำระเกิน 1 ปีขึ้นไป | E12: 95 | F12: 1703561.5 | G12: 136 | H12: 2148781.9 | I12: =E12-G12 -> -41 | J12: =F12-H12 -> -445220.44 | K12: =J12/H12*100 -> -20.719666
D13: รวมยอดหนี้ค้างชำระ | E13: =+E11+E12 -> 654 | F13: =+F12+F11 -> 3740684.4 | G13: 635 | H13: 6127586.9 | I13: =+E13-G13 -> 19 | J13: =+F13-H13 -> -2386902.4 | K13: =+J13/H13*100 -> -38.953384
C14: 2 | D14: หนี้ปรับโครงสร้างหนี้
D15: - หนี้ปรับโครงสร้างหนี้ | E15: 14 | F15: 3451894.9 | G15: 12 | H15: 969903.94 | I15: =E15-G15 -> 2 | J15: =F15-H15 -> 2481991 | K15: =+J15/H15*100 -> 255.9007
D16: รวม | E16: =SUM(E15) -> 14 | F16: =SUM(F15) -> 3451894.9 | G16: 12 | H16: 969903.94 | I16: =E16-G16 -> 2 | J16: =F16-H16 -> 2481991 | K16: =+J16/H16*100 -> 255.9007
C17: 3 | D17: หนี้บอกเลิกสัญญา
D18: -หนี้บอกเลิกสัญญา | E18: 604 | F18: 12230457 | G18: 602 | H18: 12238114 | I18: =E18-G18 -> 2 | J18: =F18-H18 -> -7656.44 | K18: =+J18/H18*100 -> -0.062562257
D19: รวม | E19: =SUM(E18) -> 604 | F19: =SUM(F18) -> 12230457 | G19: 602 | H19: 12238114 | I19: =E19-G19 -> 2 | J19: =F19-H19 -> -7656.44 | K19: =+J19/H19*100 -> -0.062562257
C20: 4 | D20: หนี้ดำเนินดคี
D21: - หนี้อยู่ระหว่างดำเนินคดี | E21: 130 | F21: 6311433.8 | G21: 127 | H21: 6226286.2 | I21: =E21-G21 -> 3 | J21: =F21-H21 -> 85147.6 | K21: =J21/H21*100 -> 1.3675504
D22: - หนี้ดำเนินคดี(ตามคำพิพากษา) | E22: 54 | F22: 41035707 | G22: 54 | H22: 41040265 | I22: =E22-G22 -> 0 | J22: =F22-H22 -> -4558.4 | K22: =J22/H22*100 -> -0.011107141
D23: รวม | E23: =+E21+E22 -> 184 | F23: =+F21+F22 -> 47347141 | G23: 181 | H23: 47266552 | I23: =+E23-G23 -> 3 | J23: =+F23-H23 -> 80589.2 | K23: =J23/H23*100 -> 0.17049943
D24: รวมยอดหนี้ค้างชำระทั้งสิ้น | E24: =+E13+E16+E19+E23 -> 1456 | F24: =+F13+F16+F19+F23+0.01 -> 66770177 | G24: 1430 | H24: 66602156 | I24: =E24-G24 -> 26 | J24: =F24-H24 -> 168021.33 | K24: =J24/H24*100 -> 0.25227611
C25: 6 | D25: การตั้งค่าเผื่อหนี้สงสัยจะสูญ | F25: =+'4.สำรองหนี้สูญ'!E22 -> 62218428 | H25: 62582277 | J25: =F25-H25 -> -363848.59 | K25: =+J25/H25*100 -> -0.58139238
D26: หนี้ค้างชำระสุทธิ | F26: =+F24-F25 -> 4551749.2 | H26: 4019879.3 | J26: =F26-H26 -> 531869.91 | K26: =J26/H26*100 -> 13.230992
C27: 5 | D27: รายการรับชำระหนี้ ประกอบด้วย | F27: =+'6.รับชำระประจำเดือน'!Z24 -> 7372333.3 | H27: 7410224.6 | J27: =F27-H27 -> -37891.25 | K27: =J27/H27*100 -> -0.5113374
D28: รวมรับชำระทั้งสิ้น | F28: =+'6.รับชำระประจำเดือน'!Z24 -> 7372333.3 | H28: 7410224.6 | J28: =F28-H28 -> -37891.25 | K28: =J28/H28*100 -> -0.5113374
