Workbook

Sheet 1.เปรียบเทียบสรุปอายุหนี้
A1: สรุปอายุลูกหนี้และยอดหนี้ค้างรับของสะพานปลาและท่าเทียบเรือประมง ณ วันที่ 31 กรกฎาคม 2569 | R1: =+A1 -> สรุปอายุลูกหนี้และยอดหนี้ค้างรับของสะพานปลาและท่าเทียบเรือประมง ณ วันที่ 31 กรกฎาคม 2569
A2: =+[1]สรุปรวมยอดหนี้ค้าง!A2 | P2: หน่วย:บาท | Q2: =+A2 | AB2: หน่วย:บาท
A3: ลำดับ | B3: หน่วยงาน | C3: รายได้อยู่ระหว่างจัดเก็บ 1 - 30 วัน | E3: รายได้อยู่ระหว่างจัดเก็บ 30 วัน ไม่เกิน 60 วัน | G3: หนี้ค้างเกิน 60 วัน ไม่เกิน 180 วัน | I3: หนี้ค้างเกิน 180 วัน ไม่เกิน 1 ปี | K3: รวมหนี้ไม่เกิน 1 ปี | M3: หนี้ค้างเกิน 1 ปีขึ้นไป | O3: รวมเป็นเงิน | Q3: หนี้ปรับโครงสร้างหนี้ | S3: หนี้บอกเลิกสัญญา | U3: หนี้ดำเนินคดี | W3: หนี้อยู่ระหว่างดำเนินคดี | Y3: รวมหนี้ดำเนินคดีเป็นเงิน | AA3: รวมหนี้ค้างชำระทั้งสิ้น
C4: จำนวน | D4: มูลค่าหนี้ | E4: จำนวน | F4: มูลค่าหนี้ | G4: จำนวน | H4: มูลค่าหนี้ | I4: จำนวน | J4: มูลค่าหนี้ | K4: จำนวน | L4: มูลค่าหนี้ | M4: จำนวน | N4: มูลค่าหนี้ | O4: จำนวน | P4: มูลค่าหนี้ | Q4: จำนวน | R4: มูลค่าหนี้ | S4: จำนวน | T4: มูลค่าหนี้ | U4: จำนวน | V4: มูลค่าหนี้ | W4: จำนวน | X4: มูลค่าหนี้ | Y4: จำนวน | Z4: มูลค่าหนี้ | AA4: จำนวน | AB4: มูลค่าหนี้ | AC4: หมายเหตุ
C5: รายการ | E5: รายการ | G5: รายการ | I5: รายการ | K5: รายการ | M5: รายการ | O5: รายการ | Q5: รายการ | S5: รายการ | U5: รายการ | W5: รายการ | Y5: รายการ | AA5: รายการ
A6: 1 | B6: สะพานปลากรุงเทพ | C6: 43 | D6: =+'[1]1 เดือน'!F56 -> 153092.66 | E6: =+'[1]2 เดือน'!A26 -> 20 | F6: =+'[1]2 เดือน'!F26 -> 296027.28 | G6: =+'[1]3-6'!A22 -> 16 | H6: =+'[1]3-6'!F22 -> 371555.93 | I6: =+'[1]7-12'!A9 -> 0 | J6: =+'[1]7-12'!F9 -> 0 | K6: =+C6+E6+G6+I6 -> 79 | L6: =+D6+F6+H6+J6 -> 820675.87 | M6: =+'[1]เกิน 12'!A8 -> 2 | N6: =+'[1]เกิน 12'!F8 -> 321800 | O6: =+K6+M6 -> 81 | P6: =+L6+N6 -> 1142475.9 | Q6: =+[1]ปรับโครงสร้างหนี้!A9 -> 3 | R6: =+[1]ปรับโครงสร้างหนี้!F9 -> 2837069.4 | S6: =+[1]หนี้บอกเลิกสัญญา!A10 -> 0 | T6: =+[1]หนี้บอกเลิกสัญญา!F10 -> 0 | U6: =+[1]หนี้ดำเนินคดี!A109 -> 38 | V6: =+[1]หนี้ดำเนินคดี!F109 -> 22923162 | W6: =+[1]อยู่ระหว่างดำเนินคดี!A26 -> 9 | X6: =+[1]อยู่ระหว่างดำเนินคดี!F26 -> 2094333.9 | Y6: =+U6+W6 -> 47 | Z6: =+V6+X6 -> 25017496 | AA6: =+K6+M6+Q6+S6+U6+W6 -> 131 | AB6: =+L6+N6+R6+T6+V6+X6 -> 28997041 | AD6: 321800 | AE6: =+N6-AD6 -> 0 | AI6: =+AH6-AB6 -> -28997041 | AJ6: 26913674 | AK6: =+AJ6-AB6 -> -2083366.9 | AQ6: 27324688 | AR6: =+AF6-AQ6 -> -27324688 | AS6: 291844.12
A7: =+A6+1 -> 2 | B7: สะพานปลาสมุทรปราการ | C7: =+'[1]1 เดือน'!A86 -> 28 | D7: =+'[1]1 เดือน'!F86 -> 72296.34 | E7: =+'[1]2 เดือน'!A30 -> 0 | F7: =+'[1]2 เดือน'!F30 -> 0 | G7: =+'[1]3-6'!A25 -> 0 | H7: =+'[1]3-6'!F25 -> 0 | I7: =+'[1]7-12'!A15 -> 4 | J7: =+'[1]7-12'!F15 -> 26201.52 | K7: =+C7+E7+G7+I7 -> 32 | L7: =+D7+F7+H7+J7 -> 98497.86 | M7: =+'[1]เกิน 12'!A11 -> 0 | N7: =+'[1]เกิน 12'!F11 -> 0 | O7: =+K7+M7 -> 32 | P7: =+L7+N7 -> 98497.86 | Q7: =+[1]ปรับโครงสร้างหนี้!A12 -> 0 | R7: =+[1]ปรับโครงสร้างหนี้!F12 -> 0 | S7: 0 | T7: 0 | U7: =+[1]หนี้ดำเนินคดี!A114 -> 3 | V7: =+[1]หนี้ดำเนินคดี!F114 -> 999772.59 | W7: 0 | X7: 0 | Y7: =+U7+W7 -> 3 | Z7: =+V7+X7 -> 999772.59 | AA7: =+K7+M7+Q7+S7+U7+W7 -> 35 | AB7: =+L7+N7+R7+T7+V7+X7 -> 1098270.5 | AD7: 0 | AE7: =+N7-AD7 -> 0 | AI7: =+AH7-AB7 -> -1098270.5 | AJ7: 1429240.7 | AK7: =+AJ7-AB7 -> 330970.29 | AQ7: 1036033.6 | AR7: =+AF7-AQ7 -> -1036033.6 | AS7: 96809.52
A8: =+A7+1 -> 3 | B8: สะพานปลาสมุทรสาคร | C8: 0 | D8: =+[1]สรุปรวมยอดหนี้ค้าง!D8-[1]เดือนก่อน!D8 -> 0 | E8: =+[1]สรุปรวมยอดหนี้ค้าง!E8-[1]เดือนก่อน!E8 -> 0 | F8: =+[1]สรุปรวมยอดหนี้ค้าง!F8-[1]เดือนก่อน!F8 -> 0 | G8: =+[1]สรุปรวมยอดหนี้ค้าง!G8-[1]เดือนก่อน!G8 -> 0 | H8: 0 | I8: =+[1]สรุปรวมยอดหนี้ค้าง!I8+[1]เดือนก่อน!I8 -> 0 | J8: =+[1]สรุปรวมยอดหนี้ค้าง!J8-[1]เดือนก่อน!J8 -> 0 | K8: =+C8+E8+G8+I8 -> 0 | L8: =+D8+F8+H8+J8 -> 0 | M8: =+'[1]เกิน 12'!A15 -> 0 | N8: =+[1]สรุปรวมยอดหนี้ค้าง!N8-[1]เดือนก่อน!N8 -> 0 | O8: =+K8+M8 -> 0 | P8: =+L8+N8 -> 0 | Q8: 0 | R8: =+N8+P8 -> 0 | S8: 0 | T8: 0 | U8: 0 | V8: 0 | W8: 0 | X8: 0 | Y8: =+U8+W8 -> 0 | Z8: =+V8+X8 -> 0 | AA8: =+K8+M8+Q8+S8+U8+W8 -> 0 | AB8: =+L8+N8+R8+T8+V8+X8 -> 0 | AD8: 0 | AE8: =+N8-AD8 -> 0 | AI8: =+AH8-AB8 -> 0 | AJ8: 0 | AK8: =+AJ8-AB8 -> 0 | AR8: =+AF8-AQ8 -> 0 | AS8: 14445
A9: =+A8+1 -> 4 | B9: ท่าเทียบเรือประมงตราด | C9: =+'[1]1 เดือน'!A92 -> 1 | D9: =+'[1]1 เดือน'!F92 -> 3327.7 | E9: =+'[1]2 เดือน'!A114 -> 0 | F9: =+'[1]2 เดือน'!F114 -> 0 | G9: =+'[1]3-6'!A32 -> 0 | H9: =+'[1]3-6'!F32 -> 0 | I9: =+'[1]7-12'!A27 -> 0 | J9: =+'[1]7-12'!F27 -> 0 | K9: =+C9+E9+G9+I9 -> 1 | L9: =+D9+F9+H9+J9 -> 3327.7 | M9: =+[1]สรุปรวมยอดหนี้ค้าง!M9-[1]เดือนก่อน!M9 -> 0 | N9: =+'[1]เกิน 12'!F11 -> 0 | O9: =+K9+M9 -> 1 | P9: =+L9+N9 -> 3327.7 | Q9: 0 | R9: =+[1]ปรับโครงสร้างหนี้!F16 -> 0 | S9: 0 | T9: 0 | U9: 0 | V9: 0 | W9: 0 | X9: 0 | Y9: =+U9+W9 -> 0 | Z9: =+V9+X9 -> 0 | AA9: =+K9+M9+Q9+S9+U9+W9 -> 1 | AB9: =+L9+N9+R9+T9+V9+X9 -> 3327.7 | AD9: 0 | AE9: =+N9-AD9 -> 0 | AI9: =+AH9-AB9 -> -3327.7 | AJ9: 31193 | AK9: =+AJ9-AB9 -> 27865.3 | AR9: =+AF9-AQ9 -> 0 | AS9: 2042100
A10: =+A9+1 -> 5 | B10: ท่าเทียบเรือประมงอ่างศิลา *** | C10: =+'[1]1 เดือน'!A163 -> 61 | D10: =+'[1]1 เดือน'!F163 -> 97061.802 | E10: =+'[1]2 เดือน'!A43 -> 7 | F10: =+'[1]2 เดือน'!F43 -> 48300 | G10: =+'[1]3-6'!A38 -> 4 | H10: =+'[1]3-6'!F38 -> 21085.2 | I10: =+'[1]7-12'!A33 -> 0 | J10: =+'[1]7-12'!F33 -> 0 | K10: =+C10+E10+G10+I10 -> 72 | L10: =+D10+F10+H10+J10 -> 166447 | M10: =+'[1]เกิน 12'!A23 -> 0 | N10: =+'[1]เกิน 12'!F23 -> 0 | O10: =+K10+M10 -> 72 | P10: =+L10+N10 -> 166447 | Q10: =+[1]ปรับโครงสร้างหนี้!A55 -> 6 | R10: =+[1]ปรับโครงสร้างหนี้!F55 -> 488577 | S10: =+[1]หนี้บอกเลิกสัญญา!A875 -> 575 | T10: =+[1]หนี้บอกเลิกสัญญา!F875 -> 11359170 | U10: 0 | V10: 0 | W10: =+[1]อยู่ระหว่างดำเนินคดี!A202 -> 107 | X10: =+[1]อยู่ระหว่างดำเนินคดี!F202 -> 3347368.1 | Y10: =+U10+W10 -> 107 | Z10: =+V10+X10 -> 3347368.1 | AA10: =+K10+M10+Q10+S10+U10+W10 -> 760 | AB10: =+L10+N10+R10+T10+V10+X10 -> 15361562 | AD10: 0 | AE10: =+N10-AD10 -> 0 | AI10: =+AH10-AB10 -> -15361562 | AJ10: 651519.5 | AK10: =+AJ10-AB10 -> -14710042 | AQ10: 7712933.2 | AR10: =+AF10-AQ10 -> -7712933.2 | AS10: 485220.7
A11: =+A10+1 -> 6 | B11: ท่าเทียบเรือประมงหัวหิน | C11: =+[1]สรุปรวมยอดหนี้ค้าง!C11-[1]เดือนก่อน!C11 -> 0 | D11: =+[1]สรุปรวมยอดหนี้ค้าง!D11-[1]เดือนก่อน!D11 -> 0 | E11: =+[1]สรุปรวมยอดหนี้ค้าง!E11-[1]เดือนก่อน!E11 -> 0 | F11: =+[1]สรุปรวมยอดหนี้ค้าง!F11-[1]เดือนก่อน!F11 -> 0 | G11: =+[1]สรุปรวมยอดหนี้ค้าง!G11-[1]เดือนก่อน!G11 -> 0 | H11: =+[1]สรุปรวมยอดหนี้ค้าง!H11-[1]เดือนก่อน!H11 -> 0 | I11: =+[1]สรุปรวมยอดหนี้ค้าง!I11+[1]เดือนก่อน!I11 -> 0 | J11: =+[1]สรุปรวมยอดหนี้ค้าง!J11-[1]เดือนก่อน!J11 -> 0 | K11: =+C11+E11+G11+I11 -> 0 | L11: =+D11+F11+H11+J11 -> 0 | M11: =+'[1]เกิน 12'!A28 -> 0 | N11: =+[1]สรุปรวมยอดหนี้ค้าง!N11-[1]เดือนก่อน!N11 -> 0 | O11: =+K11+M11 -> 0 | P11: =+L11+N11 -> 0 | Q11: 0 | R11: =+N11+P11 -> 0 | S11: 0 | T11: 0 | U11: 0 | V11: 0 | W11: 0 | X11: 0 | Y11: =+U11+W11 -> 0 | Z11: =+V11+X11 -> 0 | AA11: =+K11+M11+Q11+S11+U11+W11 -> 0 | AB11: =+L11+N11+R11+T11+V11+X11 -> 0 | AD11: 0 | AE11: =+N11-AD11 -> 0 | AI11: =+AH11-AB11 -> 0 | AJ11: 654273.63 | AK11: =+AJ11-AB11 -> 654273.63 | AQ11: 62673.63 | AR11: =+AF11-AQ11 -> -62673.63 | AS11: 21118170
A12: =+A11+1 -> 7 | B12: ท่าเทียบเรือประมงชุมพร | C12: =+'[1]1 เดือน'!A100 -> 6 | D12: =+'[1]1 เดือน'!F100 -> 23367.26 | E12: =+'[1]2 เดือน'!A54 -> 0 | F12: =+'[1]2 เดือน'!F54 -> 0 | G12: =+'[1]3-6'!A42 -> 0 | H12: =+'[1]3-6'!F42 -> 0 | I12: =+'[1]7-12'!A39 -> 0 | J12: =+'[1]7-12'!F39 -> 0 | K12: =+C12+E12+G12+I12 -> 6 | L12: =+D12+F12+H12+J12 -> 23367.26 | M12: =+'[1]เกิน 12'!A32 -> 0 | N12: =+'[1]เกิน 12'!F32 -> 0 | O12: =+K12+M12 -> 6 | P12: =+L12+N12 -> 23367.26 | Q12: =+[1]ปรับโครงสร้างหนี้!A25 -> 0 | R12: =+[1]ปรับโครงสร้างหนี้!F25 -> 0 | S12: =+[1]หนี้บอกเลิกสัญญา!A878 -> 0 | T12: =+[1]หนี้บอกเลิกสัญญา!F878 -> 0 | U12: 0 | V12: 0 | W12: =+[1]อยู่ระหว่างดำเนินคดี!A207 -> 3 | X12: =+[1]อยู่ระหว่างดำเนินคดี!F207 -> 518359.52 | Y12: =+U12+W12 -> 3 | Z12: =+V12+X12 -> 518359.52 | AA12: =+K12+M12+Q12+S12+U12+W12 -> 9 | AB12: =+L12+N12+R12+T12+V12+X12 -> 541726.78 | AD12: 0 | AE12: =+N12-AD12 -> 0 | AI12: =+AH12-AB12 -> -541726.78 | AJ12: 945601.12 | AK12: =+AJ12-AB12 -> 403874.34 | AQ12: 657989.42 | AR12: =+AF12-AQ12 -> -657989.42 | AS12: 63865.35
A13: =+A12+1 -> 8 | B13: ท่าเทียบเรือประมงหลังสวน | C13: =+'[1]1 เดือน'!A166 -> 0 | D13: =+'[1]1 เดือน'!F166 -> 0 | E13: =+'[1]2 เดือน'!A47 -> 0 | F13: =+[1]สรุปรวมยอดหนี้ค้าง!F13-[1]เดือนก่อน!F13 -> 0 | G13: =+[1]สรุปรวมยอดหนี้ค้าง!G13-[1]เดือนก่อน!G13 -> 0 | H13: =+[1]สรุปรวมยอดหนี้ค้าง!H13-[1]เดือนก่อน!H13 -> 0 | I13: =+[1]สรุปรวมยอดหนี้ค้าง!I13+[1]เดือนก่อน!I13 -> 0 | J13: =+[1]สรุปรวมยอดหนี้ค้าง!J13-[1]เดือนก่อน!J13 -> 0 | K13: =+C13+E13+G13+I13 -> 0 | L13: =+D13+F13+H13+J13 -> 0 | M13: =+'[1]เกิน 12'!A148 -> 0 | N13: =+'[1]เกิน 12'!F148 -> 0 | O13: =+K13+M13 -> 0 | P13: =+L13+N13 -> 0 | Q13: =+[1]ปรับโครงสร้างหนี้!A32 -> 0 | R13: =+[1]ปรับโครงสร้างหนี้!F32 -> 0 | S13: 0 | T13: 0 | U13: =+[1]หนี้ดำเนินคดี!A120 -> 0 | V13: =+[1]หนี้ดำเนินคดี!F120 -> 0 | W13: 0 | X13: 0 | Y13: =+U13+W13 -> 0 | Z13: =+V13+X13 -> 0 | AA13: =+K13+M13+Q13+S13+U13+W13 -> 0 | AB13: =+L13+N13+R13+T13+V13+X13 -> 0 | AD13: 0 | AE13: =+N13-AD13 -> 0 | AI13: =+AH13-AB13 -> 0 | AJ13: 291714.77 | AK13: =+AJ13-AB13 -> 291714.77 | AQ13: 288906.02 | AR13: =+AF13-AQ13 -> -288906.02 | AS13: 3212233.6
A14: =+A13+1 -> 9 | B14: ท่าเทียบเรือประมงสุราษฎร์ธานี | C14: =+'[1]1 เดือน'!A174 -> 0 | D14: =+'[1]1 เดือน'!F174 -> 0 | E14: =+[1]สรุปรวมยอดหนี้ค้าง!E14-[1]เดือนก่อน!E14 -> 0 | F14: =+[1]สรุปรวมยอดหนี้ค้าง!F14-[1]เดือนก่อน!F14 -> 0 | G14: =+[1]สรุปรวมยอดหนี้ค้าง!G14-[1]เดือนก่อน!G14 -> 0 | H14: =+[1]สรุปรวมยอดหนี้ค้าง!H14-[1]เดือนก่อน!H14 -> 0 | I14: =+[1]สรุปรวมยอดหนี้ค้าง!I14+[1]เดือนก่อน!I14 -> 0 | J14: =+[1]สรุปรวมยอดหนี้ค้าง!J14-[1]เดือนก่อน!J14 -> 0 | K14: =+C14+E14+G14+I14 -> 0 | L14: =+D14+F14+H14+J14 -> 0 | M14: =+[1]สรุปรวมยอดหนี้ค้าง!M14-[1]เดือนก่อน!M14 -> 0 | N14: =+[1]สรุปรวมยอดหนี้ค้าง!N14-[1]เดือนก่อน!N14 -> 0 | O14: =+K14+M14 -> 0 | P14: =+L14+N14 -> 0 | Q14: =+E14+G14+I14+L14+O14 -> 0 | R14: =+N14+P14 -> 0 | S14: 0 | T14: 0 | U14: =+[1]หนี้ดำเนินคดี!A123 -> 1 | V14: =+[1]หนี้ดำเนินคดี!F123 -> 5530855.9 | W14: 0 | X14: 0 | Y14: =+U14+W14 -> 1 | Z14: =+V14+X14 -> 5530855.9 | AA14: =+K14+M14+Q14+S14+U14+W14 -> 1 | AB14: =+L14+N14+R14+T14+V14+X14 -> 5530855.9 | AD14: 0 | AE14: =+N14-AD14 -> 0 | AI14: =+AH14-AB14 -> -5530855.9 | AJ14: 5569595.2 | AK14: =+AJ14-AB14 -> 38739.25 | AQ14: 5530855.9 | AR14: =+AF14-AQ14 -> -5530855.9 | AS14: =SUM(AS6:AS13) -> 27324688
A15: =+A14+1 -> 10 | B15: สะพานปลานครศรีธรรมราช | C15: =+'[1]1 เดือน'!A177 -> 0 | D15: =+'[1]1 เดือน'!F177 -> 0 | E15: =+'[1]2 เดือน'!A60 -> 0 | F15: =+'[1]2 เดือน'!F60 -> 0 | G15: =+'[1]3-6'!A52 -> 4 | H15: =+'[1]3-6'!F52 -> 3487.02 | I15: =+'[1]7-12'!A46 -> 0 | J15: =+[1]สรุปรวมยอดหนี้ค้าง!J15-[1]เดือนก่อน!J15 -> 0 | K15: =+C15+E15+G15+I15 -> 4 | L15: =+D15+F15+H15+J15 -> 3487.02 | M15: =+'[1]เกิน 12'!A40 -> 0 | N15: =+'[1]เกิน 12'!F40 -> 0 | O15: =+K15+M15 -> 4 | P15: =+L15+N15 -> 3487.02 | Q15: =+[1]ปรับโครงสร้างหนี้!A37 -> 0 | R15: =+[1]ปรับโครงสร้างหนี้!F37 -> 0 | S15: =+[1]หนี้บอกเลิกสัญญา!A881 -> 1 | T15: =+[1]หนี้บอกเลิกสัญญา!F881 -> 10408.5 | U15: 0 | V15: 0 | W15: 0 | X15: 0 | Y15: =+U15+W15 -> 0 | Z15: =+V15+X15 -> 0 | AA15: =+K15+M15+Q15+S15+U15+W15 -> 5 | AB15: =+L15+N15+R15+T15+V15+X15 -> 13895.52 | AD15: 0 | AE15: =+N15-AD15 -> 0 | AI15: =+AH15-AB15 -> -13895.52 | AJ15: 15100.95 | AK15: =+AJ15-AB15 -> 1205.43 | AQ15: 12288.76 | AR15: =+AF15-AQ15 -> -12288.76
A16: =+A15+1 -> 11 | B16: ท่าเทียบเรือประมงสงขลา | C16: =+[1]สรุปรวมยอดหนี้ค้าง!C16-[1]เดือนก่อน!C16 -> 0 | D16: =+[1]สรุปรวมยอดหนี้ค้าง!D16-[1]เดือนก่อน!D16 -> 0 | E16: =+[1]สรุปรวมยอดหนี้ค้าง!E16-[1]เดือนก่อน!E16 -> 0 | F16: =+[1]สรุปรวมยอดหนี้ค้าง!F16-[1]เดือนก่อน!F16 -> 0 | G16: =+[1]สรุปรวมยอดหนี้ค้าง!G16-[1]เดือนก่อน!G16 -> 0 | H16: =+[1]สรุปรวมยอดหนี้ค้าง!H16-[1]เดือนก่อน!H16 -> 0 | I16: =+[1]สรุปรวมยอดหนี้ค้าง!I16+[1]เดือนก่อน!I16 -> 0 | J16: =+[1]สรุปรวมยอดหนี้ค้าง!J16-[1]เดือนก่อน!J16 -> 0 | K16: =+C16+E16+G16+I16 -> 0 | L16: =+D16+F16+H16+J16 -> 0 | M16: =+[1]สรุปรวมยอดหนี้ค้าง!M16-[1]เดือนก่อน!M16 -> 0 | N16: =+[1]สรุปรวมยอดหนี้ค้าง!N16-[1]เดือนก่อน!N16 -> 0 | O16: =+K16+M16 -> 0 | P16: =+L16+N16 -> 0 | Q16: 0 | R16: 0 | S16: 0 | T16: 0 | U16: 0 | V16: 0 | W16: 0 | X16: 0 | Y16: =+U16+W16 -> 0 | Z16: =+V16+X16 -> 0 | AA16: =+K16+M16+Q16+S16+U16+W16 -> 0 | AB16: =+L16+N16+R16+T16+V16+X16 -> 0 | AD16: 0 | AE16: =+N16-AD16 -> 0 | AI16: =+AH16-AB16 -> 0 | AJ16: 0 | AK16: =+AJ16-AB16 -> 0 | AR16: =+AF16-AQ16 -> 0 | AS16: 403098.64
A17: =+A16+1 -> 12 | B17: ท่าเทียบเรือประมงสงขลา(ท่าสะอ้าน) | C17: =+'[1]1 เดือน'!A430 -> 63 | D17: =+'[1]1 เดือน'!F430 -> 139609.18 | E17: =+'[1]2 เดือน'!A66 -> 0 | F17: =+'[1]2 เดือน'!F66 -> 0 | G17: =+'[1]3-6'!A57 -> 0 | H17: =+'[1]3-6'!F57 -> 0 | I17: =+'[1]7-12'!A96 -> 0 | J17: =+'[1]7-12'!F96 -> 0 | K17: =+C17+E17+G17+I17 -> 63 | L17: =+D17+F17+H17+J17 -> 139609.18 | M17: =+'[1]เกิน 12'!A43 -> 0 | N17: =+'[1]เกิน 12'!F43 -> 0 | O17: =+K17+M17 -> 63 | P17: =+L17+N17 -> 139609.18 | Q17: =+[1]ปรับโครงสร้างหนี้!A40 -> 1 | R17: =+[1]ปรับโครงสร้างหนี้!F40 -> 14471.5 | S17: =+[1]หนี้บอกเลิกสัญญา!A941 -> 0 | T17: =+[1]หนี้บอกเลิกสัญญา!F941 -> 0 | U17: =+[1]หนี้ดำเนินคดี!A134 -> 2 | V17: =+[1]หนี้ดำเนินคดี!F134 -> 421250.36 | W17: =+[1]อยู่ระหว่างดำเนินคดี!A224 -> 5 | X17: =+[1]อยู่ระหว่างดำเนินคดี!F224 -> 83772.3 | Y17: =+U17+W17 -> 7 | Z17: =+V17+X17 -> 505022.66 | AA17: =+K17+M17+Q17+S17+U17+W17 -> 71 | AB17: =+L17+N17+R17+T17+V17+X17 -> 659103.34 | AD17: 0 | AE17: =+N17-AD17 -> 0 | AI17: =+AH17-AB17 -> -659103.34 | AJ17: 822198.32 | AK17: =+AJ17-AB17 -> 163094.98 | AQ17: 733240.35 | AR17: =+AF17-AQ17 -> -733240.35 | AS17: 2042100
A18: =+A17+1 -> 13 | B18: ท่าเทียบเรือประมงระนอง | C18: =+'[1]1 เดือน'!A365 -> 12 | D18: =+'[1]1 เดือน'!F365 -> 27551.423 | E18: =+'[1]2 เดือน'!A69 -> 1 | F18: =+'[1]2 เดือน'!F69 -> 96.3 | G18: =+[1]สรุปรวมยอดหนี้ค้าง!G18-[1]เดือนก่อน!G18 -> 0 | H18: =+[1]สรุปรวมยอดหนี้ค้าง!H18-[1]เดือนก่อน!H18 -> 0 | I18: 0 | J18: =+[1]สรุปรวมยอดหนี้ค้าง!J18-[1]เดือนก่อน!J18 -> 0 | K18: =+C18+E18+G18+I18 -> 13 | L18: =+D18+F18+H18+J18 -> 27647.723 | M18: =+'[1]เกิน 12'!A46 -> 0 | N18: =+'[1]เกิน 12'!F46 -> 0 | O18: =+K18+M18 -> 13 | P18: =+L18+N18 -> 27647.723 | Q18: =+[1]ปรับโครงสร้างหนี้!A43 -> 0 | R18: =+[1]ปรับโครงสร้างหนี้!F43 -> 0 | S18: 0 | T18: 0 | U18: =+[1]หนี้ดำเนินคดี!A146 -> 2 | V18: =+[1]หนี้ดำเนินคดี!F146 -> 9044331 | W18: =+[1]อยู่ระหว่างดำเนินคดี!A212 -> 0 | X18: =+[1]อยู่ระหว่างดำเนินคดี!F212 -> 0 | Y18: =+U18+W18 -> 2 | Z18: =+V18+X18 -> 9044331 | AA18: =+K18+M18+Q18+S18+U18+W18 -> 15 | AB18: =+L18+N18+R18+T18+V18+X18 -> 9071978.7 | AD18: 0 | AE18: =+N18-AD18 -> 0 | AI18: =+AH18-AB18 -> -9071978.7 | AJ18: 9039191.9 | AK18: =+AJ18-AB18 -> -32786.763 | AQ18: 8701630.1 | AR18: =+AF18-AQ18 -> -8701630.1 | AS18: 63865.35
A19: =+A18+1 -> 14 | B19: ท่าเทียบเรือประมงปัตตานี | C19: =+'[1]1 เดือน'!A351 -> 172 | D19: =+'[1]1 เดือน'!F351 -> 197067.17 | E19: =+'[1]2 เดือน'!A94 -> 23 | F19: =+'[1]2 เดือน'!F94 -> 25895 | G19: =+'[1]3-6'!A92 -> 30 | H19: =+'[1]3-6'!F92 -> 125063.5 | I19: =+'[1]7-12'!A65 -> 9 | J19: =+'[1]7-12'!F65 -> 37021 | K19: =+C19+E19+G19+I19 -> 234 | L19: =+D19+F19+H19+J19 -> 385046.67 | M19: =+'[1]เกิน 12'!A133 -> 85 | N19: =+'[1]เกิน 12'!F133 -> 1155065.6 | O19: =+K19+M19 -> 319 | P19: =+L19+N19 -> 1540112.2 | Q19: =+[1]ปรับโครงสร้างหนี้!A47 -> 1 | R19: =+[1]ปรับโครงสร้างหนี้!F47 -> 10977 | S19: =+[1]หนี้บอกเลิกสัญญา!A937 -> 19 | T19: =+[1]หนี้บอกเลิกสัญญา!F937 -> 513079.01 | U19: =+[1]หนี้ดำเนินคดี!A117 -> 1 | V19: =+[1]หนี้ดำเนินคดี!F117 -> 39933.51 | W19: =+[1]อยู่ระหว่างดำเนินคดี!A217 -> 2 | X19: =+[1]อยู่ระหว่างดำเนินคดี!F217 -> 91700 | Y19: =+U19+W19 -> 3 | Z19: =+V19+X19 -> 131633.51 | AA19: =+K19+M19+Q19+S19+U19+W19 -> 342 | AB19: =+L19+N19+R19+T19+V19+X19 -> 2195801.7 | AD19: 1401472.9 | AE19: =+N19-AD19 -> -246407.38 | AI19: =+AH19-AB19 -> -2195801.7 | AJ19: 3898901.1 | AK19: =+AJ19-AB19 -> 1703099.4 | AQ19: 1057364.8 | AR19: =+AF19-AQ19 -> -1057364.8 | AS19: 21118170
A20: =+A19+1 -> 15 | B20: ท่าเทียบเรือประมงนราธิวาส | C20: =+'[1]1 เดือน'!A435 -> 0 | D20: =+'[1]1 เดือน'!F435 -> 0 | E20: =+'[1]2 เดือน'!A111 -> 0 | F20: =+'[1]2 เดือน'!F111 -> 0 | G20: =+'[1]3-6'!A99 -> 0 | H20: =+'[1]3-6'!F99 -> 0 | I20: =+[1]สรุปรวมยอดหนี้ค้าง!I20+[1]เดือนก่อน!I20 -> 0 | J20: =+[1]สรุปรวมยอดหนี้ค้าง!J20-[1]เดือนก่อน!J20 -> 0 | K20: =+C20+E20+G20+I20 -> 0 | L20: =+D20+F20+H20+J20 -> 0 | M20: =+'[1]เกิน 12'!A141 -> 6 | N20: =+'[1]เกิน 12'!F141 -> 195600 | O20: =+K20+M20 -> 6 | P20: =+L20+N20 -> 195600 | Q20: =+[1]ปรับโครงสร้างหนี้!A60 -> 3 | R20: =+[1]ปรับโครงสร้างหนี้!F60 -> 100800 | S20: =+[1]หนี้บอกเลิกสัญญา!A963 -> 9 | T20: =+[1]หนี้บอกเลิกสัญญา!F963 -> 347800 | U20: =+[1]หนี้ดำเนินคดี!A168 -> 0 | V20: =+[1]หนี้ดำเนินคดี!F168 -> 0 | W20: =+[1]อยู่ระหว่างดำเนินคดี!A237 -> 1 | X20: =+[1]อยู่ระหว่างดำเนินคดี!F237 -> 39100 | Y20: =+U20+W20 -> 1 | Z20: =+V20+X20 -> 39100 | AA20: =+K20+M20+Q20+S20+U20+W20 -> 19 | AB20: =+L20+N20+R20+T20+V20+X20 -> 683300 | AD20: 219200 | AE20: =+N20-AD20 -> -23600 | AI20: =+AH20-AB20 -> -683300 | AJ20: 946200 | AK20: =+AJ20-AB20 -> 262900 | AQ20: 899400 | AR20: =+AF20-AQ20 -> -899400 | AS20: 3212233.6
A21: =+A20+1 -> 16 | B21: ท่าเทียบเรือประมงภูเก็ต | C21: =+'[1]1 เดือน'!A470 -> 33 | D21: =+'[1]1 เดือน'!F470 -> 191268.33 | E21: =+'[1]2 เดือน'!A103 -> 3 | F21: =+'[1]2 เดือน'!F103 -> 45030.9 | G21: =+'[1]3-6'!A102 -> 0 | H21: =+'[1]3-6'!F102 -> 0 | I21: =+'[1]7-12'!A88 -> 16 | J21: =+'[1]7-12'!F88 -> 103697.45 | K21: =+C21+E21+G21+I21 -> 52 | L21: =+D21+F21+H21+J21 -> 339996.68 | M21: =+'[1]เกิน 12'!A145 -> 2 | N21: =+'[1]เกิน 12'!F145 -> 31095.896 | O21: =+K21+M21 -> 54 | P21: =+L21+N21+0.01 -> 371092.58 | Q21: 0 | R21: 0 | S21: =+[1]หนี้บอกเลิกสัญญา!A952 -> 0 | T21: =+[1]หนี้บอกเลิกสัญญา!F952 -> 0 | U21: =+[1]หนี้ดำเนินคดี!A154 -> 4 | V21: =+[1]หนี้ดำเนินคดี!F154 -> 1363508.4 | W21: =+[1]อยู่ระหว่างดำเนินคดี!A228 -> 0 | X21: =+[1]อยู่ระหว่างดำเนินคดี!F228 -> 0 | Y21: =+U21+W21 -> 4 | Z21: =+V21+X21 -> 1363508.4 | AA21: =+K21+M21+Q21+S21+U21+W21 -> 58 | AB21: =+L21+N21+R21+T21+V21+X21+0.01 -> 1734601 | AD21: 32160.336 | AE21: =+N21-AD21 -> -1064.44 | AI21: =+AH21-AB21 -> -1734601 | AJ21: 5240446.1 | AK21: =+AJ21-AB21 -> 3505845.1 | AQ21: 4540259.7 | AR21: =+AF21-AQ21 -> -4540259.7
A22: =+A21+1 -> 17 | B22: ท่าเทียบเรือประมงสตูล | C22: =+'[1]1 เดือน'!A475 -> 0 | D22: =+'[1]1 เดือน'!F475 -> 0 | E22: =+'[1]2 เดือน'!A107 -> 2 | F22: =+'[1]2 เดือน'!F107 -> 19300 | G22: =+'[1]3-6'!A105 -> 1 | H22: =+'[1]3-6'!F105 -> 9720 | I22: =+'[1]7-12'!A93 -> 0 | J22: =+'[1]7-12'!F93 -> 0 | K22: =+C22+E22+G22+I22 -> 3 | L22: =+D22+F22+H22+J22 -> 29020 | M22: =+'[1]เกิน 12'!A153 -> 0 | N22: =+'[1]เกิน 12'!F153 -> 0 | O22: =+K22+M22 -> 3 | P22: =+L22+N22 -> 29020 | Q22: =+[1]ปรับโครงสร้างหนี้!A66 -> 0 | R22: =+[1]ปรับโครงสร้างหนี้!F66 -> 0 | S22: 0 | T22: 0 | U22: =+[1]หนี้ดำเนินคดี!A165 -> 3 | V22: =+[1]หนี้ดำเนินคดี!F165 -> 712893.26 | W22: =+[1]อยู่ระหว่างดำเนินคดี!A234 -> 3 | X22: =+[1]อยู่ระหว่างดำเนินคดี!F234 -> 136800 | Y22: =+U22+W22 -> 6 | Z22: =+V22+X22 -> 849693.26 | AA22: =+K22+M22+Q22+S22+U22+W22 -> 9 | AB22: =+L22+N22+R22+T22+V22+X22 -> 878713.26 | AD22: 0 | AE22: =+N22-AD22 -> 0 | AI22: =+AH22-AB22 -> -878713.26 | AJ22: 685739.3 | AK22: =+AJ22-AB22 -> -192973.96 | AQ22: 680124.8 | AR22: =+AF22-AQ22 -> -680124.8
B23: รวมเป็นเงิน | C23: =SUM(C6:C22) -> 419 | D23: =SUM(D6:D22) -> 904641.86 | E23: =SUM(E6:E22) -> 56 | F23: =SUM(F6:F22) -> 434649.48 | G23: =SUM(G6:G22) -> 55 | H23: =SUM(H6:H22) -> 530911.65 | I23: =SUM(I6:I22) -> 29 | J23: =SUM(J6:J22) -> 166919.97 | ... AA23: =SUM(AA6:AA22) -> 1456 | AB23: =SUM(AB6:AB22)+0.01 -> 66770177 | AE23: =SUM(AE6:AE22) -> -271071.82 | AI23: =+AH23-AB23 -> -66770177
B24: หนี้ค้างชำระเดือน มิถุนายน 2569 | C24: 359 | D24: 983968.03 | E24: 72 | F24: 380362.04 | G24: 46 | H24: 2531382 | I24: 22 | J24: 83092.899 | K24: 499 | L24: 3978805 | M24: 136 | N24: 2148781.9 | O24: 635 | P24: 6127586.9 | Q24: 12 | R24: 969903.94 | S24: 602 | T24: 12238114 | U24: 54 | V24: 41040265 | W24: 127 | X24: 6226286.2 | Y24: 181 | Z24: 47266552 | AA24: 1430 | AB24: 66602156
B25: เพิ่ม (ลด) | C25: =+C23-C24 -> 60 | D25: =+D23-D24 -> -79326.172 | E25: =+E23-E24 -> -16 | F25: =+F23-F24 -> 54287.44 | G25: =+G23-G24 -> 9 | H25: =+H23-H24 -> -2000470.3 | I25: =+I23-I24 -> 7 | J25: =+J23-J24 -> 83827.071 | ... AB25: =+AB23-AB24 -> 168021.33
B31: ปรับยอดภูเก็ต+0.01
N51: 365937.62
A52: สรุป | B52: ยอดหนีค้างชำระ 1 วัน - เกิน 1 ปีขึ้นไป | D52: =+D23+F23+H23+J23+N23 -> 3740684.4 | AB52: 56677411
B53: ยอดหนี้ดำเนินคดี | D53: =+#REF!+V23+X23 -> #REF!
B54: รวมยอดหนี้ค้างทั้งสิ้น | D54: =SUM(D52:D53) -> #REF!
A56: 1 | B56: สะพานปลากรุงเทพ | C56: 38 | D56: =+D6*0.0287 -> 4393.7593 | E56: 70 | F56: =+F6*0.0287 -> 8495.9829 | G56: 3 | H56: =+H6*0.0287 -> 10663.655 | I56: 4 | J56: =J6*0.0287 -> 0 | M56: 7 | N56: =+N6 -> 321800 | O56: 122 | P56: =+N56+J56+H56+F56+D56 -> 345353.4 | R56: =+R6*0.0287 -> 81423.893 | U56: 58 | V56: 21192764 | W56: 13 | X56: 3010698.6 | Y56: 73 | Z56: =+X56+V56+#REF! -> #REF! | AA56: 195 | AB56: =+Z56+R56+P56 -> #REF!
A57: 2 | B57: สะพานปลาสมุทรปราการ | C57: 46 | D57: =+D7*0.0287 -> 2074.905 | E57: 2 | F57: =+F7*0.0287 -> 0 | G57: 2 | H57: =+H7*0.0287 -> 0 | I57: 2 | J57: =J7*0.0287 -> 751.98362 | N57: =+N7 -> 0 | O57: 52 | P57: =+N57+J57+H57+F57+D57 -> 2826.8886 | R57: =+R7*0.0287 -> 0 | U57: 3 | V57: 999772.59 | Y57: 3 | Z57: =+X57+V57+#REF! -> #REF! | AA57: 55 | AB57: =+Z57+R57+P57 -> #REF!
A58: 3 | B58: สะพานปลาสมุทรสาคร | C58: 0 | D58: =+D8*0.0287 -> 0 | F58: =+F8*0.0287 -> 0 | H58: =+H8*0.0287 -> 0 | J58: =J8*0.0287 -> 0 | N58: =+N8 -> 0 | P58: =+N58+J58+H58+F58+D58 -> 0 | R58: =+R8*0.0287 -> 0 | Z58: =+X58+V58+#REF! -> #REF! | AA58: 0 | AB58: =+Z58+R58+P58 -> #REF!
A59: 4 | B59: ท่าเทียบเรือประมงตราด | C59: 2 | D59: =+D9*0.0287 -> 95.50499 | F59: =+F9*0.0287 -> 0 | G59: 0 | H59: =+H9*0.0287 -> 0 | J59: =J9*0.0287 -> 0 | N59: =+N9 -> 0 | O59: 2 | P59: =+N59+J59+H59+F59+D59 -> 95.50499 | R59: =+R9*0.0287 -> 0 | Z59: =+X59+V59+#REF! -> #REF! | AA59: 2 | AB59: =+Z59+R59+P59 -> #REF!
A60: 5 | B60: ท่าเทียบเรือประมงอ่างศิลา *** | C60: 287 | D60: =+D10*0.0287 -> 2785.6737 | E60: 135 | F60: =+F10*0.0287 -> 1386.21 | G60: 231 | H60: =+H10*0.0287 -> 605.14524 | I60: 92 | J60: =J10*0.0287 -> 0 | N60: =+N10 -> 0 | O60: 745 | P60: =+N60+J60+H60+F60+D60 -> 4777.029 | R60: =+R10*0.0287 -> 14022.16 | Z60: =+X60+V60+#REF! -> #REF! | AA60: 745 | AB60: =+Z60+R60+P60 -> #REF!
A61: 6 | B61: ท่าเทียบเรือประมงหัวหิน | D61: =+D11*0.0287 -> 0 | F61: =+F11*0.0287 -> 0 | H61: =+H11*0.0287 -> 0 | J61: =J11*0.0287 -> 0 | N61: =+N11 -> 0 | O61: 0 | P61: =+N61+J61+H61+F61+D61 -> 0 | R61: =+R11*0.0287 -> 0 | U61: 1 | V61: 62673.63 | Y61: 1 | Z61: =+X61+V61+#REF! -> #REF! | AA61: 1 | AB61: =+Z61+R61+P61 -> #REF!
A62: 7 | B62: ท่าเทียบเรือประมงชุมพร | C62: 23 | D62: =+D12*0.0287 -> 670.64036 | E62: 4 | F62: =+F12*0.0287 -> 0 | G62: 4 | H62: =+H12*0.0287 -> 0 | I62: 6 | J62: =J12*0.0287 -> 0 | M62: 3 | N62: =+N12 -> 0 | O62: 40 | P62: =+N62+J62+H62+F62+D62 -> 670.64036 | Q62: 6 | R62: =+R12*0.0287 -> 0 | Z62: =+X62+V62+#REF! -> #REF! | AA62: 46 | AB62: =+Z62+R62+P62 -> #REF!
A63: 8 | B63: ท่าเทียบเรือประมงหลังสวน | C63: 1 | D63: =+D13*0.0287 -> 0 | F63: =+F13*0.0287 -> 0 | H63: =+H13*0.0287 -> 0 | J63: =J13*0.0287 -> 0 | N63: =+N13 -> 0 | O63: 1 | P63: =+N63+J63+H63+F63+D63 -> 0 | R63: =+R13*0.0287 -> 0 | U63: 1 | V63: 288906.02 | Y63: 1 | Z63: =+X63+V63+#REF! -> #REF! | AA63: 2 | AB63: =+Z63+R63+P63 -> #REF!
A64: 9 | B64: ท่าเทียบเรือประมงสุราษฎร์ธานี | C64: 10 | D64: =+D14*0.0287 -> 0 | E64: 0 | F64: =+F14*0.0287 -> 0 | G64: 2 | H64: =+H14*0.0287 -> 0 | J64: =J14*0.0287 -> 0 | N64: =+N14 -> 0 | O64: 12 | P64: =+N64+J64+H64+F64+D64 -> 0 | R64: =+R14*0.0287 -> 0 | U64: 1 | V64: 5530855.9 | Y64: 1 | Z64: =+X64+V64+#REF! -> #REF! | AA64: 13 | AB64: =+Z64+R64+P64 -> #REF!
A65: 10 | B65: สะพานปลานครศรีธรรมราช | C65: 4 | D65: =+D15*0.0287 -> 0 | E65: 0 | F65: =+F15*0.0287 -> 0 | G65: 0 | H65: =+H15*0.0287 -> 100.07747 | J65: =J15*0.0287 -> 0 | M65: 3 | N65: =+N15 -> 0 | O65: 7 | P65: =+N65+J65+H65+F65+D65 -> 100.07747 | R65: =+R15*0.0287 -> 0 | Z65: =+X65+V65+#REF! -> #REF! | AA65: 7 | AB65: =+Z65+R65+P65 -> #REF!
...
